<?xml version="1.0" ?>
<robot xmlns:xacro="http://ros.org/wiki/xacro">
	<xacro:macro name="irb_2400" params="prefix">
		<!-- link list -->
		<link name="${prefix}base_link">
			<visual>
     			<origin
        		xyz="0 0 0"
       			rpy="0 0 0" />
      			<geometry>
        			<mesh
          			filename="package://abb_common/meshes/irb_2400/visual/base_link.STL" />
      			</geometry>
      			<material
        			name="abb_orange">
        			<color
          			rgba="1 0.43 0 1" />
      			</material>
    		</visual>
 			<collision>
				<geometry>
					<mesh filename="package://abb_common/meshes/irb_2400/collision/base_link.STL" />
				</geometry>
				<material name="yellow">
					<color rgba="0 1 1 1"/>
				</material>
			</collision>

		</link>
		<link name="${prefix}link_1">
			<visual>
      			<origin
        			xyz="0 0 0"
        			rpy="0 0 0" />
      			<geometry>
        			<mesh
          			filename="package://abb_common/meshes/irb_2400/visual/link_1.STL" />
      			</geometry>
      			<material name="abb_orange"/>
    		</visual>
			<collision>
      			<origin
        			xyz="0 0 0"
        			rpy="0 0 0" />
				<geometry>
					<mesh filename="package://abb_common/meshes/irb_2400/collision/link_1.STL" />
				</geometry>
				<material name="yellow"/>
			</collision>

		</link>
		<link name="${prefix}link_2">
		    <visual>
      			<origin
        			xyz="0 0 0"
        			rpy="0 0 0" />
      			<geometry>
        			<mesh
          			filename="package://abb_common/meshes/irb_2400/visual/link_2.STL" />
      			</geometry>
      			<material name="abb_orange"/>
    		</visual>
			<collision>
      			<origin
        			xyz="0 0 0"
        			rpy="0 0 0" />
				<geometry>
					<mesh filename="package://abb_common/meshes/irb_2400/collision/link_2_whole.STL" />
				</geometry>
				<material name="yellow"/>
			</collision>

		</link>
		<link name="${prefix}link_3">
			<visual>
				<origin
					xyz="0 0 0"
					rpy="0 0 0" />
			  	<geometry>
					<mesh
				  	filename="package://abb_common/meshes/irb_2400/visual/link_3.STL" />
			  	</geometry>
			  	<material name="abb_orange"/>
			</visual>
			<collision>
      			<origin
        			xyz="0 0 0"
        			rpy="0 0 0" />
				<geometry>
					<mesh filename="package://abb_common/meshes/irb_2400/collision/link_3.STL" />
				</geometry>
				<material name="yellow"/>
			</collision>

		</link>
		<link name="${prefix}link_4">
			<visual>
				  <origin
					xyz="0 0 0"
					rpy="0 0 0" />
				  <geometry>
					<mesh
					  filename="package://abb_common/meshes/irb_2400/visual/link_4.STL" />
				  </geometry>
				  <material name="abb_orange"/>
			</visual>
			<collision>
      			<origin
        			xyz="0 0 0"
        			rpy="0 0 0" />
				<geometry>
					<mesh filename="package://abb_common/meshes/irb_2400/collision/link_4.STL" />
				</geometry>
				<material name="yellow"/>
			</collision>

		</link>
		<link name="${prefix}link_5">
			<visual>
				<origin
					xyz="0 0 0"
					rpy="0 0 0" />
				<geometry>
					<mesh
					  filename="package://abb_common/meshes/irb_2400/visual/link_5.STL" />
				</geometry>
				<material name="abb_orange"/>
			</visual>
			<collision>
      			<origin
        			xyz="0 0 0"
        			rpy="0 0 0" />
				<geometry>
					<mesh filename="package://abb_common/meshes/irb_2400/collision/link_5.STL" />
				</geometry>
				<material name="yellow"/>
			</collision>

		</link>
		<link name="${prefix}link_6">
			<visual>
				<origin
					xyz="0 0 0"
					rpy="0 0 0" />
				<geometry>
					<mesh
					  filename="package://abb_common/meshes/irb_2400/visual/link_6.STL" />
				</geometry>
				<material name="abb_orange"/>
			</visual>
			<collision>
      			<origin
        			xyz="0 0 0"
        			rpy="0 0 0" />
				<geometry>
					<mesh filename="package://abb_common/meshes/irb_2400/collision/link_6.STL" />
				</geometry>
				<material name="yellow"/>
			</collision>

		</link>
		<link name="${prefix}tool0"/>
		<!-- end of link list -->

		<!-- joint list -->
		<joint name="${prefix}joint_1" type="revolute">
			<origin
			  xyz="0 0 0"
			  rpy="0 0 0" />
			<parent
			  link="${prefix}base_link" />
			<child
			  link="${prefix}link_1" />
			<axis
			  xyz="0 0 1" />
			<limit
			  lower="-3.1416"
			  upper="3.1416"
			  effort="0"
			  velocity="2.618" />
			<calibration
			  rising="0"
			  falling="0" />
			<dynamics
			  damping="0"
			  friction="0" />
		</joint>
		<joint name="${prefix}joint_2" type="revolute">
			<origin
			  xyz="0.1 0 0.615"
			  rpy="0 0 0" />
			<parent
			  link="${prefix}link_1" />
			<child
			  link="${prefix}link_2" />
			<axis
			  xyz="0 1 0" />
			<limit
			  lower="-1.7453"
			  upper="1.9199"
			  effort="0"
			  velocity="2.618" />
			<calibration
			  rising="0"
			  falling="0" />
			<dynamics
			  damping="0"
			  friction="0" />
  		</joint>
		<joint name="${prefix}joint_3" type="revolute">
			<origin
			  xyz="0 0 0.705"
			  rpy="0 0 0" />
			<parent
			  link="${prefix}link_2" />
			<child
			  link="${prefix}link_3" />
			<axis
			  xyz="0 1 0" />
			<limit
			  lower="-1.0472"
			  upper="1.1345"
			  effort="0"
			  velocity="2.618" />
			<calibration
			  rising="0"
			  falling="0" />
			<dynamics
			  damping="0"
			  friction="0" />
		</joint>
		<joint name="${prefix}joint_4" type="revolute">
			<origin
			  xyz="0.258 0 0.135"
			  rpy="0 0 0" />
			<parent
			  link="${prefix}link_3" />
			<child
			  link="${prefix}link_4" />
			<axis
			  xyz="1 0 0" />
			<limit
			  lower="-3.49"
			  upper="3.49"
			  effort="0"
			  velocity="6.2832" />
			<calibration
			  rising="0"
			  falling="0" />
			<dynamics
			  damping="0"
			  friction="0" />
		</joint>
		<joint name="${prefix}joint_5" type="revolute">
			<origin
			  xyz="0.497 0 0"
			  rpy="0 0 0" />
			<parent
			  link="${prefix}link_4" />
			<child
			  link="${prefix}link_5" />
			<axis
			  xyz="0 1 0" />
			<limit
			  lower="-2.0944"
			  upper="2.0944"
			  effort="0"
			  velocity="6.2832" />
			<calibration
			  rising="0"
			  falling="0" />
			<dynamics
			  damping="0"
			  friction="0" />
		</joint>
		<joint name="${prefix}joint_6" type="revolute">
			<origin
			  xyz="0.085 0 0"
			  rpy="0 0 0" />
			<parent
			  link="${prefix}link_5" />
			<child
			  link="${prefix}link_6" />
			<axis
			  xyz="1 0 0" />
			<limit
			  lower="-6.9813"
			  upper="6.9813"
			  effort="0"
			  velocity="7.854" />
			<calibration
			  rising="0"
			  falling="0" />
			<dynamics
			  damping="0"
			  friction="0" />
		</joint>
		<joint name="${prefix}joint_6-tool0" type="fixed">
			<parent link="${prefix}link_6"/>
			<child link="${prefix}tool0"/>
			<origin xyz="0 0 0" rpy="0 0 0"/>
		</joint>
		<!-- end of joint list -->
	</xacro:macro>
</robot>
