<?xml version="1.0" ?>
<!-- =================================================================================== -->
<!-- |    This document was autogenerated by xacro from irb_5400.xacro                 | -->
<!-- |    EDITING THIS FILE BY HAND IS NOT RECOMMENDED                                 | -->
<!-- =================================================================================== -->
<robot name="irb_5400" xmlns:xacro="http://ros.org/wiki/xacro">
  <link name="base_link">
    <visual>
      <geometry>
        <mesh filename="package://abb_common/meshes/irb_5400/visual/BASE_LINK.STL"/>
      </geometry>
      <material name="orange">
        <color rgba="1 0.43 0 1"/>
      </material>
    </visual>
    <collision>
      <geometry>
        <mesh filename="package://abb_common/meshes/irb_5400/collision/BASE_LINK.STL"/>
      </geometry>
      <material name="yellow">
        <color rgba="0 1 1 1"/>
      </material>
    </collision>
  </link>
  <link name="link_1">
    <visual>
      <geometry>
        <mesh filename="package://abb_common/meshes/irb_5400/visual/LINK_1.STL"/>
      </geometry>
      <material name="orange"/>
    </visual>
    <collision>
      <geometry>
        <mesh filename="package://abb_common/meshes/irb_5400/collision/LINK_1.STL"/>
      </geometry>
      <material name="yellow"/>
    </collision>
  </link>
  <link name="link_2">
    <visual>
      <geometry>
        <mesh filename="package://abb_common/meshes/irb_5400/visual/LINK_2.STL"/>
      </geometry>
      <material name="lt_black">
        <color rgba="0.3 0.3 0.3 1"/>
      </material>
    </visual>
    <collision>
      <geometry>
        <mesh filename="package://abb_common/meshes/irb_5400/collision/LINK_2.STL"/>
      </geometry>
      <material name="yellow"/>
    </collision>
  </link>
  <link name="link_3">
    <visual>
      <geometry>
        <mesh filename="package://abb_common/meshes/irb_5400/visual/LINK_3.STL"/>
      </geometry>
      <material name="orange"/>
    </visual>
    <collision>
      <geometry>
        <mesh filename="package://abb_common/meshes/irb_5400/collision/LINK_3.STL"/>
      </geometry>
      <material name="yellow"/>
    </collision>
  </link>
  <link name="link_4">
    <visual>
      <geometry>
        <mesh filename="package://abb_common/meshes/irb_5400/visual/LINK_4.STL"/>
      </geometry>
      <material name="lt_black"/>
    </visual>
    <collision>
      <geometry>
        <mesh filename="package://abb_common/meshes/irb_5400/collision/LINK_4.STL"/>
      </geometry>
      <material name="yellow"/>
    </collision>
  </link>
  <link name="link_5">
    <visual>
      <geometry>
        <mesh filename="package://abb_common/meshes/irb_5400/visual/LINK_5.STL"/>
      </geometry>
      <material name="lt_black"/>
    </visual>
    <collision>
      <geometry>
        <mesh filename="package://abb_common/meshes/irb_5400/collision/LINK_5.STL"/>
      </geometry>
      <material name="yellow"/>
    </collision>
  </link>
  <link name="link_6">
    <visual>
      <geometry>
        <mesh filename="package://abb_common/meshes/irb_5400/visual/LINK_6.STL"/>
      </geometry>
      <material name="lt_black"/>
    </visual>
    <collision>
      <geometry>
        <mesh filename="package://abb_common/meshes/irb_5400/collision/LINK_6.STL"/>
      </geometry>
      <material name="yellow"/>
    </collision>
  </link>
  <link name="tool0"/>
  <joint name="joint1" type="revolute">
    <parent link="base_link"/>
    <child link="link_1"/>
    <origin rpy="0 0 0" xyz="0 0 0"/>
    <axis xyz="0 0 1"/>
    <limit effort="100" lower="-2.617" upper="2.617" velocity="2.3911"/>
  </joint>
  <joint name="joint2" type="revolute">
    <parent link="link_1"/>
    <child link="link_2"/>
    <origin rpy="0 0 0" xyz="0.300 0 0.660"/>
    <axis xyz="0 1 0"/>
    <limit effort="100" lower="-1.396" upper="1.396" velocity="2.3911"/>
  </joint>
  <joint name="joint3" type="revolute">
    <parent link="link_2"/>
    <child link="link_3"/>
    <origin rpy="0 0 0" xyz="0 0 1.200"/>
    <axis xyz="0 1 0"/>
    <limit effort="100" lower="-1.308" upper="1.308" velocity="2.3911"/>
  </joint>
  <joint name="joint4" type="revolute">
    <parent link="link_3"/>
    <child link="link_4"/>
    <origin rpy="0 0 0" xyz="1.339 0 0.186"/>
    <axis xyz="1 0 0"/>
    <limit effort="100" lower="-6.0" upper="6.0" velocity="8.1157"/>
  </joint>
  <joint name="joint5" type="revolute">
    <parent link="link_4"/>
    <child link="link_5"/>
    <origin rpy="0 0.6109 0" xyz="0.0693 0 0"/>
    <axis xyz="1 0 0"/>
    <limit effort="100" lower="-6.0" upper="6.0" velocity="6.1086"/>
  </joint>
  <joint name="joint6" type="revolute">
    <parent link="link_5"/>
    <child link="link_6"/>
    <origin rpy="0 -1.2217 0" xyz=".106246 0 0.074394"/>
    <axis xyz="1 0 0"/>
    <limit effort="100" lower="-6.0" upper="6.0" velocity="9.3375"/>
  </joint>
  <joint name="joint_6-tool0" type="fixed">
    <parent link="link_6"/>
    <child link="tool0"/>
    <origin rpy="0.0 0.6109 0.0" xyz="0.0672 0 -0.0470"/>
  </joint>
</robot>

