<?xml version="1.0" ?>
<!-- =================================================================================== -->
<!-- |    This document was autogenerated by xacro from workcell.xacro                 | -->
<!-- |    EDITING THIS FILE BY HAND IS NOT RECOMMENDED                                 | -->
<!-- =================================================================================== -->
<robot name="sia20d_workcell" xmlns:xacro="http://ros.org/wiki/xacro">
  <link name="front_wall">
    <visual>
      <geometry>
        <box size=".02 2.397 1.0"/>
      </geometry>
      <material name="orange_transparent">
        <color rgba="1 0.5 0 0.2"/>
      </material>
    </visual>
    <collision>
      <geometry>
        <box size=".02 2.397 1.0"/>
      </geometry>
      <material name="orange_transparent"/>
    </collision>
  </link>
  <link name="right_wall">
    <visual>
      <geometry>
        <box size="1.2 .02 1"/>
      </geometry>
      <material name="orange_transparent"/>
    </visual>
    <collision>
      <geometry>
        <box size="1.2 .02 1"/>
      </geometry>
      <material name="orange_transparent"/>
    </collision>
  </link>
  <link name="left_wall">
    <visual>
      <geometry>
        <box size="1.2 .02 1"/>
      </geometry>
      <material name="orange_transparent"/>
    </visual>
    <collision>
      <geometry>
        <box size="1.2 .02 1"/>
      </geometry>
      <material name="orange_transparent"/>
    </collision>
  </link>
  <link name="diag_wall">
    <visual>
      <geometry>
        <box size=".75 .02 1"/>
      </geometry>
      <material name="orange_transparent"/>
    </visual>
    <collision>
      <geometry>
        <box size=".75 .02 1"/>
      </geometry>
      <material name="orange_transparent"/>
    </collision>
  </link>
  <link name="back_wall">
    <visual>
      <geometry>
        <box size=".02 2.099 1"/>
      </geometry>
      <material name="orange_transparent"/>
    </visual>
    <collision>
      <geometry>
        <box size=".02 2.099 1"/>
      </geometry>
      <material name="orange_transparent"/>
    </collision>
  </link>
  <link name="floor">
    <visual>
      <geometry>
        <box size="1.25 2.4 .1"/>
      </geometry>
      <material name="orange_transparent"/>
    </visual>
    <collision>
      <geometry>
        <box size="1.25 2.4 .1"/>
      </geometry>
      <material name="orange_transparent"/>
    </collision>
  </link>
  <joint name="base_to_front" type="fixed">
    <parent link="base_link"/>
    <child link="front_wall"/>
    <origin rpy="0 0 0" xyz="1.06 0 .5"/>
  </joint>
  <joint name="base_to_right" type="fixed">
    <parent link="base_link"/>
    <child link="right_wall"/>
    <origin rpy="0 0 -.14" xyz=".45 -1.124 0.5"/>
  </joint>
  <joint name="base_to_left" type="fixed">
    <parent link="base_link"/>
    <child link="left_wall"/>
    <origin rpy="0 0 .14" xyz=".45 1.124 0.5"/>
  </joint>
  <joint name="base_to_diag" type="fixed">
    <parent link="base_link"/>
    <child link="diag_wall"/>
    <origin rpy="0 0 .785" xyz=".788 -.851 0.5"/>
  </joint>
  <joint name="base_to_back" type="fixed">
    <parent link="base_link"/>
    <child link="back_wall"/>
    <origin xyz="-.25 0 0.5"/>
  </joint>
  <joint name="base_to_floor" type="fixed">
    <parent link="base_link"/>
    <child link="floor"/>
    <origin xyz=".45 0 -0.05"/>
  </joint>
  <link name="base_link">
    <visual>
      <geometry>
        <mesh filename="package://motoman_config/meshes/sia20d/visual/MOTOMAN_BASE.stl"/>
      </geometry>
      <material name="blue">
        <color rgba="0 0 1 1"/>
      </material>
    </visual>
    <collision>
      <geometry>
        <mesh filename="package://motoman_config/meshes/sia20d/collision/MOTOMAN_BASE.stl"/>
      </geometry>
      <material name="yellow">
        <color rgba="0 1 1 1"/>
      </material>
    </collision>
  </link>
  <link name="link_s">
    <visual>
      <origin rpy="0 0 3.1416" xyz="0 0 0"/>
      <geometry>
        <mesh filename="package://motoman_config/meshes/sia20d/visual/MOTOMAN_AXIS_S.stl"/>
      </geometry>
      <material name="silver">
        <color rgba="0.8 0.8 0.8 1"/>
      </material>
    </visual>
    <collision>
      <origin rpy="0 0 3.1416" xyz="0 0 0"/>
      <geometry>
        <mesh filename="package://motoman_config/meshes/sia20d/collision/MOTOMAN_AXIS_S.stl"/>
      </geometry>
      <material name="yellow"/>
    </collision>
  </link>
  <link name="link_l">
    <visual>
      <origin rpy="1.57 3.1416 3.1416" xyz="0 0 0"/>
      <geometry>
        <mesh filename="package://motoman_config/meshes/sia20d/visual/MOTOMAN_AXIS_L.stl"/>
      </geometry>
      <material name="blue"/>
    </visual>
    <collision>
      <origin rpy="1.57 3.1416 3.1416" xyz="0 0 0"/>
      <geometry>
        <mesh filename="package://motoman_config/meshes/sia20d/collision/MOTOMAN_AXIS_L.stl"/>
      </geometry>
      <material name="yellow"/>
    </collision>
  </link>
  <link name="link_e">
    <visual>
      <origin rpy="0 0 0" xyz="0 0 0"/>
      <geometry>
        <mesh filename="package://motoman_config/meshes/sia20d/visual/MOTOMAN_AXIS_E.stl"/>
      </geometry>
      <material name="silver"/>
    </visual>
    <collision>
      <origin rpy="0 0 0" xyz="0 0 0"/>
      <geometry>
        <mesh filename="package://motoman_config/meshes/sia20d/collision/MOTOMAN_AXIS_E.stl"/>
      </geometry>
      <material name="yellow"/>
    </collision>
  </link>
  <link name="link_u">
    <visual>
      <origin rpy="1.57 -3.1415 3.1416" xyz="0 0 0"/>
      <geometry>
        <mesh filename="package://motoman_config/meshes/sia20d/visual/MOTOMAN_AXIS_U.stl"/>
      </geometry>
      <material name="blue"/>
    </visual>
    <collision>
      <origin rpy="1.57 -3.1415 3.1416" xyz="0 0 0"/>
      <geometry>
        <mesh filename="package://motoman_config/meshes/sia20d/collision/MOTOMAN_AXIS_U.stl"/>
      </geometry>
      <material name="yellow"/>
    </collision>
  </link>
  <link name="link_r">
    <visual>
      <origin rpy="0 0 0" xyz="0 0 0"/>
      <geometry>
        <mesh filename="package://motoman_config/meshes/sia20d/visual/MOTOMAN_AXIS_R.stl"/>
      </geometry>
      <material name="silver"/>
    </visual>
    <collision>
      <origin rpy="0 0 0" xyz="0 0 0"/>
      <geometry>
        <mesh filename="package://motoman_config/meshes/sia20d/collision/MOTOMAN_AXIS_R.stl"/>
      </geometry>
      <material name="yellow"/>
    </collision>
  </link>
  <link name="link_b">
    <visual>
      <origin rpy="-1.57 0 0" xyz="0 0 0"/>
      <geometry>
        <mesh filename="package://motoman_config/meshes/sia20d/visual/MOTOMAN_AXIS_B.stl"/>
      </geometry>
      <material name="blue"/>
    </visual>
    <collision>
      <origin rpy="-1.57 0 0" xyz="0 0 0"/>
      <geometry>
        <mesh filename="package://motoman_config/meshes/sia20d/collision/MOTOMAN_AXIS_B.stl"/>
      </geometry>
      <material name="yellow"/>
    </collision>
  </link>
  <link name="link_t">
    <visual>
      <geometry>
        <mesh filename="package://motoman_config/meshes/sia20d/visual/MOTOMAN_AXIS_T.stl"/>
      </geometry>
      <material name="silver"/>
    </visual>
    <collision>
      <geometry>
        <mesh filename="package://motoman_config/meshes/sia20d/collision/MOTOMAN_AXIS_T.stl"/>
      </geometry>
      <material name="yellow"/>
    </collision>
  </link>
  <link name="tool0"/>
  <joint name="joint_s" type="revolute">
    <parent link="base_link"/>
    <child link="link_s"/>
    <origin rpy="0 0 0" xyz="0 0 0.41"/>
    <axis xyz="0 0 1"/>
    <limit effort="100" lower="-3.1416" upper="3.1416" velocity="2.26"/>
  </joint>
  <joint name="joint_l" type="revolute">
    <parent link="link_s"/>
    <child link="link_l"/>
    <origin rpy="0 0 0" xyz="0 0 0"/>
    <axis xyz="0 1 0"/>
    <limit effort="100" lower="-1.91" upper="1.91" velocity="2.26"/>
  </joint>
  <joint name="joint_e" type="revolute">
    <parent link="link_l"/>
    <child link="link_e"/>
    <origin rpy="0 0 0" xyz="0 0 0.49"/>
    <axis xyz="0 0 1"/>
    <limit effort="100" lower="-2.96" upper="2.96" velocity="2.96"/>
  </joint>
  <joint name="joint_u" type="revolute">
    <parent link="link_e"/>
    <child link="link_u"/>
    <origin rpy="0 0 0" xyz="0 0 0"/>
    <axis xyz="0 -1 0"/>
    <limit effort="100" lower="-2.26" upper="2.26" velocity="2.96"/>
  </joint>
  <joint name="joint_r" type="revolute">
    <parent link="link_u"/>
    <child link="link_r"/>
    <origin rpy="0 0 0" xyz="0 0 0.420"/>
    <axis xyz="0 0 -1"/>
    <limit effort="100" lower="-3.1416" upper="3.1416" velocity="3.48"/>
  </joint>
  <joint name="joint_b" type="revolute">
    <parent link="link_r"/>
    <child link="link_b"/>
    <origin rpy="0 0 0" xyz="0 0 0"/>
    <axis xyz="0 -1 0"/>
    <limit effort="100" lower="-1.91" upper="1.91" velocity="3.48"/>
  </joint>
  <joint name="joint_t" type="revolute">
    <parent link="link_b"/>
    <child link="link_t"/>
    <origin rpy="0 0 0" xyz="0 0 0.18"/>
    <axis xyz="0 0 -1"/>
    <limit effort="100" lower="-3.1416" upper="3.1416" velocity="6.97"/>
  </joint>
  <joint name="link_t-tool0" type="fixed">
    <origin rpy="0 -1.571 0" xyz="0 0 0.0"/>
    <parent link="link_t"/>
    <child link="tool0"/>
  </joint>
</robot>

