<?xml version="1.0" ?>
<robot name="universal_robot">

  <link name="base_link"/>

  <joint name="shoulder_pan_joint" type="revolute">
    <parent link="base_link"/>
    <child link="shoulder_link"/>
    <origin rpy="0.0 0.0 0.0" xyz="0.0 0.0 0.1"/>
    <axis xyz="0.0 0.0 1.0"/>
    <limit effort="10.0" lower="-3.14" upper="3.14" velocity="1.0"/>
  </joint>

  <link name="shoulder_link">
    <visual>
      <geometry>
        <cylinder length="0.1" radius="0.1"/>
      </geometry>
      <origin rpy="0.0 0.0 0.0" xyz="0.0 0.0 -0.05"/>
    </visual>
    <collision>
      <geometry>
        <cylinder length="0.1" radius="0.1"/>
      </geometry>
      <origin rpy="0.0 0.0 0.0" xyz="0.0 0.0 -0.05"/>
    </collision>
  </link>

  <joint name="shoulder_lift_joint" type="revolute">
    <parent link="shoulder_link"/>
    <child link="upper_arm_link"/>
    <origin rpy="0.0 0.0 0.0" xyz="0.0 0.1 0.0"/>
    <axis xyz="0.0 1.0 0.0"/>
    <limit effort="10.0" lower="-3.14" upper="3.14" velocity="1.0"/>
  </joint>

  <link name="upper_arm_link">
    <visual>
      <geometry>
        <cylinder length="0.5" radius="0.05"/>
      </geometry>
      <origin rpy="0.0 0.0 0.0" xyz="0.0 0.0 0.25"/>
    </visual>
    <collision>
      <geometry>
        <cylinder length="0.5" radius="0.05"/>
      </geometry>
      <origin rpy="0.0 0.0 0.0" xyz="0.0 0.0 0.25"/>
    </collision>
  </link>

  <joint name="elbow_joint" type="revolute">
    <parent link="upper_arm_link"/>
    <child link="forearm_link"/>
    <origin rpy="0.0 0.0 0.0" xyz="0.0 -0.1 0.5"/>
    <axis xyz="0.0 -1.0 0.0"/>
    <limit effort="10.0" lower="-3.14" upper="3.14" velocity="1.0"/>
  </joint>

  <link name="forearm_link">
    <visual>
      <geometry>
        <cylinder length="0.5" radius="0.03"/>
      </geometry>
      <origin rpy="0.0 0.0 0.0" xyz="0.0 0.0 0.25"/>
    </visual>
    <collision>
      <geometry>
        <cylinder length="0.5" radius="0.03"/>
      </geometry>
      <origin rpy="0.0 0.0 0.0" xyz="0.0 0.0 0.25"/>
    </collision>
  </link>

  <joint name="wrist_1_joint" type="revolute">
    <parent link="forearm_link"/>
    <child link="wrist_1_link"/>
    <origin rpy="0.0 0.0 0.0" xyz="0.0 0.0 0.5"/>
    <axis xyz="0.0 1.0 0.0"/>
    <limit effort="10.0" lower="-3.14" upper="3.14" velocity="1.0"/>
  </joint>

  <link name="wrist_1_link">
    <visual>
      <geometry>
        <cylinder length="0.1" radius="0.03"/>
      </geometry>
      <origin rpy="-1.57 0.0 0.0" xyz="0.0 0.05 0.0"/>
    </visual>
    <collision>
      <geometry>
        <cylinder length="0.1" radius="0.03"/>
      </geometry>
      <origin rpy="-1.57 0.0 0.0" xyz="0.0 0.05 0.0"/>
    </collision>
  </link>

  <joint name="wrist_2_joint" type="revolute">
    <parent link="wrist_1_link"/>
    <child link="wrist_2_link"/>
    <origin rpy="0.0 0.0 0.0" xyz="0.0 0.1 0.0"/>
    <axis xyz="0.0 0.0 1.0"/>
    <limit effort="10.0" lower="-3.14" upper="3.14" velocity="1.0"/>
  </joint>

  <link name="wrist_2_link">
    <visual>
      <geometry>
        <cylinder length="0.1" radius="0.03"/>
      </geometry>
      <origin rpy="0.0 0.0 0.0" xyz="0.0 0.0 0.05"/>
    </visual>
    <collision>
      <geometry>
        <cylinder length="0.1" radius="0.03"/>
      </geometry>
      <origin rpy="0.0 0.0 0.0" xyz="0.0 0.0 0.05"/>
    </collision>
  </link>

  <joint name="wrist_3_joint" type="revolute">
    <parent link="wrist_2_link"/>
    <child link="wrist_3_link"/>
    <origin rpy="0.0 0.0 0.0" xyz="0.0 0.0 0.1"/>
    <axis xyz="0.0 1.0 0.0"/>
    <limit effort="10.0" lower="-3.14" upper="3.14" velocity="1.0"/>
  </joint>

  <link name="wrist_3_link">
    <visual>
      <geometry>
        <cylinder length="0.1" radius="0.03"/>
      </geometry>
      <origin rpy="-1.57 0.0 0.0" xyz="0.0 0.05 0.0"/>
    </visual>
    <collision>
      <geometry>
        <cylinder length="0.1" radius="0.03"/>
      </geometry>
      <origin rpy="-1.57 0.0 0.0" xyz="0.0 0.05 0.0"/>
    </collision>
  </link>

  <joint name="ee_fixed_joint" type="fixed">
    <parent link="wrist_3_link"/>
    <child link="ee_link"/>
    <origin rpy="0.0 0.0 1.57" xyz="0.0 0.1 0.0"/>
  </joint>

  <link name="ee_link">
    <visual>
      <geometry>
        <cylinder length="0.01" radius="0.06"/>
      </geometry>
      <origin rpy="0.0 -1.57 0.0" xyz="0.0 0.0 0.0"/>
    </visual>
    <collision>
      <geometry>
        <cylinder length="0.01" radius="0.06"/>
      </geometry>
      <origin rpy="0.0 -1.57 0.0" xyz="0.0 0.0 0.0"/>
    </collision>
  </link>

</robot>

