<?xml version="1.0" ?>
<!-- =================================================================================== -->
<!-- |    This document was autogenerated by xacro from robot.urdf.xacro               | -->
<!-- |    EDITING THIS FILE BY HAND IS NOT RECOMMENDED                                 | -->
<!-- =================================================================================== -->
<robot name="robot" xmlns:xacro="http://www.ros.org/wiki/xacro">
  <!-- Create links -->
  <link name="world"/>
  <link name="base_link"/>
  <joint name="panda_joint_base_link" type="fixed">
    <parent link="base_link"/>
    <child link="panda_link0"/>
    <origin rpy="0 0 0" xyz="0 0 0"/>
  </joint>
  <link name="panda_link0">
    <visual>
      <geometry>
        <mesh filename="package://pick_and_place_support/meshes/visual/link0.dae"/>
      </geometry>
    </visual>
    <collision>
      <geometry>
        <mesh filename="package://pick_and_place_support/meshes/collision/link0.stl"/>
      </geometry>
    </collision>
  </link>
  <link name="panda_link1">
    <visual>
      <geometry>
        <mesh filename="package://pick_and_place_support/meshes/visual/link1.dae"/>
      </geometry>
    </visual>
    <collision>
      <geometry>
        <mesh filename="package://pick_and_place_support/meshes/collision/link1.stl"/>
      </geometry>
    </collision>
  </link>
  <joint name="panda_joint1" type="revolute">
    <safety_controller k_position="100.0" k_velocity="40.0" soft_lower_limit="-2.8973" soft_upper_limit="2.8973"/>
    <origin rpy="0 0 0" xyz="0 0 0.333"/>
    <parent link="panda_link0"/>
    <child link="panda_link1"/>
    <axis xyz="0 0 1"/>
    <limit effort="87" lower="-2.9671" upper="2.9671" velocity="2.1750"/>
  </joint>
  <link name="panda_link2">
    <visual>
      <geometry>
        <mesh filename="package://pick_and_place_support/meshes/visual/link2.dae"/>
      </geometry>
    </visual>
    <collision>
      <geometry>
        <mesh filename="package://pick_and_place_support/meshes/collision/link2.stl"/>
      </geometry>
    </collision>
  </link>
  <joint name="panda_joint2" type="revolute">
    <safety_controller k_position="100.0" k_velocity="40.0" soft_lower_limit="-1.7628" soft_upper_limit="1.7628"/>
    <origin rpy="-1.57079632679 0 0" xyz="0 0 0"/>
    <parent link="panda_link1"/>
    <child link="panda_link2"/>
    <axis xyz="0 0 1"/>
    <limit effort="87" lower="-1.8326" upper="1.8326" velocity="2.1750"/>
  </joint>
  <link name="panda_link3">
    <visual>
      <geometry>
        <mesh filename="package://pick_and_place_support/meshes/visual/link3.dae"/>
      </geometry>
    </visual>
    <collision>
      <geometry>
        <mesh filename="package://pick_and_place_support/meshes/collision/link3.stl"/>
      </geometry>
    </collision>
  </link>
  <joint name="panda_joint3" type="revolute">
    <safety_controller k_position="100.0" k_velocity="40.0" soft_lower_limit="-2.8973" soft_upper_limit="2.8973"/>
    <origin rpy="1.57079632679 0 0" xyz="0 -0.316 0"/>
    <parent link="panda_link2"/>
    <child link="panda_link3"/>
    <axis xyz="0 0 1"/>
    <limit effort="87" lower="-2.9671" upper="2.9671" velocity="2.1750"/>
  </joint>
  <link name="panda_link4">
    <visual>
      <geometry>
        <mesh filename="package://pick_and_place_support/meshes/visual/link4.dae"/>
      </geometry>
    </visual>
    <collision>
      <geometry>
        <mesh filename="package://pick_and_place_support/meshes/collision/link4.stl"/>
      </geometry>
    </collision>
  </link>
  <joint name="panda_joint4" type="revolute">
    <safety_controller k_position="100.0" k_velocity="40.0" soft_lower_limit="-3.0718" soft_upper_limit="-0.0698"/>
    <origin rpy="1.57079632679 0 0" xyz="0.0825 0 0"/>
    <parent link="panda_link3"/>
    <child link="panda_link4"/>
    <axis xyz="0 0 1"/>
    <limit effort="87" lower="-3.1416" upper="0.0" velocity="2.1750"/>
  </joint>
  <link name="panda_link5">
    <visual>
      <geometry>
        <mesh filename="package://pick_and_place_support/meshes/visual/link5.dae"/>
      </geometry>
    </visual>
    <collision>
      <geometry>
        <mesh filename="package://pick_and_place_support/meshes/collision/link5.stl"/>
      </geometry>
    </collision>
  </link>
  <joint name="panda_joint5" type="revolute">
    <safety_controller k_position="100.0" k_velocity="40.0" soft_lower_limit="-2.8973" soft_upper_limit="2.8973"/>
    <origin rpy="-1.57079632679 0 0" xyz="-0.0825 0.384 0"/>
    <parent link="panda_link4"/>
    <child link="panda_link5"/>
    <axis xyz="0 0 1"/>
    <limit effort="12" lower="-2.9671" upper="2.9671" velocity="2.6100"/>
  </joint>
  <link name="panda_link6">
    <visual>
      <geometry>
        <mesh filename="package://pick_and_place_support/meshes/visual/link6.dae"/>
      </geometry>
    </visual>
    <collision>
      <geometry>
        <mesh filename="package://pick_and_place_support/meshes/collision/link6.stl"/>
      </geometry>
    </collision>
  </link>
  <joint name="panda_joint6" type="revolute">
    <safety_controller k_position="100.0" k_velocity="40.0" soft_lower_limit="-0.0175" soft_upper_limit="3.7525"/>
    <origin rpy="1.57079632679 0 0" xyz="0 0 0"/>
    <parent link="panda_link5"/>
    <child link="panda_link6"/>
    <axis xyz="0 0 1"/>
    <limit effort="12" lower="-0.0873" upper="3.8223" velocity="2.6100"/>
  </joint>
  <link name="panda_link7">
    <visual>
      <geometry>
        <mesh filename="package://pick_and_place_support/meshes/visual/link7.dae"/>
      </geometry>
    </visual>
    <collision>
      <geometry>
        <mesh filename="package://pick_and_place_support/meshes/collision/link7.stl"/>
      </geometry>
    </collision>
  </link>
  <joint name="panda_joint7" type="revolute">
    <safety_controller k_position="100.0" k_velocity="40.0" soft_lower_limit="-2.8973" soft_upper_limit="2.8973"/>
    <origin rpy="1.57079632679 0 0" xyz="0.088 0 0"/>
    <parent link="panda_link6"/>
    <child link="panda_link7"/>
    <axis xyz="0 0 1"/>
    <limit effort="12" lower="-2.9671" upper="2.9671" velocity="2.6100"/>
  </joint>
  <link name="panda_link8"/>
  <joint name="panda_joint8" type="fixed">
    <origin rpy="0 0 0" xyz="0 0 0.107"/>
    <parent link="panda_link7"/>
    <child link="panda_link8"/>
    <axis xyz="0 0 0"/>
  </joint>
  <material name="light_gray">
    <color rgba="0.7 0.7 0.7 1"/>
  </material>
  <material name="red">
    <color rgba="1.0 0.1 0.1 1"/>
  </material>
  <link name="workcell_base">
    <visual>
      <geometry>
        <mesh filename="package://pick_and_place_support/meshes/workcell.STL"/>
      </geometry>
      <material name="light_gray"/>
    </visual>
    <collision name="workcell_table">
      <geometry>
        <box size="0.8 1.25 0.77153"/>
      </geometry>
      <origin xyz="0.0 0.3 -0.385765"/>
    </collision>
    <collision name="workcell_columnSW">
      <geometry>
        <box size="0.1 0.1 1.25"/>
      </geometry>
      <origin xyz="-.3302 -.2794 0.6"/>
    </collision>
    <collision name="workcell_columnsSE">
      <geometry>
        <box size="0.1 0.1 1.25"/>
      </geometry>
      <origin xyz=".3302 -.2794 0.6"/>
    </collision>
    <collision name="workcell_columnNW">
      <geometry>
        <box size="0.1 0.1 1.25"/>
      </geometry>
      <origin xyz="-.3302 0.8382 0.6"/>
      colors
    
    </collision>
    <collision name="workcell_columnNE">
      <geometry>
        <box size="0.1 0.1 1.25"/>
      </geometry>
      <origin xyz=".3302 0.8382 0.6"/>
    </collision>
    <collision name="workcell_top">
      <geometry>
        <box size="0.95 1.4 0.2"/>
      </geometry>
      <origin xyz="0.0 0.3 1.2"/>
    </collision>
  </link>
  <joint name="workcell_joint" type="fixed">
    <origin rpy="0 0 0" xyz="0.0 0.0 0.77153"/>
    <parent link="world"/>
    <child link="workcell_base"/>
  </joint>
  <link name="shelf_1">
    <visual>
      <geometry>
        <mesh filename="package://pick_and_place_support/meshes/shelf.STL"/>
      </geometry>
      <material name="light_gray"/>
    </visual>
    <collision name="shelf_1_back">
      <geometry>
        <box size="0.9144 0.05 1.8288"/>
      </geometry>
      <origin xyz="0.4572 0.0 0.9144"/>
    </collision>
    <collision name="shelf_1_sideL">
      <geometry>
        <box size="0.05 0.5096 1.8288"/>
      </geometry>
      <origin xyz="0.025 0.22 0.9144"/>
    </collision>
    <collision name="shelf_1_sideR">
      <geometry>
        <box size="0.05 0.5096 1.8288"/>
      </geometry>
      <origin xyz=".945 0.22 0.9144"/>
    </collision>
    <collision name="shelf_1_shelf1">
      <geometry>
        <box size="0.9144 0.5096 0.05"/>
      </geometry>
      <origin xyz=".4572 0.22 0.025"/>
    </collision>
    <collision name="shelf_1_shelf2">
      <geometry>
        <box size="0.9144 0.5096 0.05"/>
      </geometry>
      <origin xyz=".4572 0.22 0.6346"/>
    </collision>
    <collision name="shelf_1_shelf3">
      <geometry>
        <box size="0.9144 0.5096 0.05"/>
      </geometry>
      <origin xyz=".4572 0.22 1.2442"/>
    </collision>
    <collision name="shelf_1_shelf4">
      <geometry>
        <box size="0.9144 0.5096 0.05"/>
      </geometry>
      <origin xyz=".4572 0.22 1.8038"/>
    </collision>
  </link>
  <joint name="shelf_1_joint" type="fixed">
    <origin rpy="0 0 4.7124" xyz="-0.85 0.8 0.11"/>
    <parent link="world"/>
    <child link="shelf_1"/>
  </joint>
  <!-- Create joints -->
  <joint name="workcell_base_to_base" type="fixed">
    <parent link="workcell_base"/>
    <child link="base_link"/>
    <origin rpy="0 0 1.5708" xyz="0 0 0.00953"/>
  </joint>
  <!--
    <joint name="base_to_panda_link0" type="fixed">
      <parent link="base_link"/>
      <child link="panda_link0"/>
      <origin xyz="0 0 0" rpy="0 0 0"/>
    </joint>
-->
</robot>
