<?xml version="1.0"?>
<robot xmlns:xacro="http://ros.org/wiki/xacro">
	<xacro:macro name="m430ia2f" params="prefix">


		<!-- links -->
		<link name="${prefix}base_link">
			<visual>
				<origin xyz="0 0 0" rpy="0 0 0"/>
				<geometry>
					<mesh filename="package://fanuc_config/meshes/m430ia2f/visual/base_link.stl"/>
				</geometry>
				<material name="white">
					<color rgba="0.9 0.9 0.9 1"/>
				</material>
			</visual>
			<collision>
				<origin xyz="0 0 0" rpy="0 0 0"/>
				<geometry>
					<mesh filename="package://fanuc_config/meshes/m430ia2f/collision/base_link.stl"/>
				</geometry>
			</collision>
		</link>
		<link name="${prefix}link_1">
			<visual>
				<origin xyz="0 0 0" rpy="0 0 0"/>
				<geometry>
					<mesh filename="package://fanuc_config/meshes/m430ia2f/visual/link_1.stl"/>
				</geometry>
				<material name="">
					<color rgba="0.89804 0.89804 0.89804 1"/>
				</material>
			</visual>
			<collision>
				<origin xyz="0 0 0" rpy="0 0 0"/>
				<geometry>
					<mesh filename="package://fanuc_config/meshes/m430ia2f/collision/link_1.stl"/>
				</geometry>
			</collision>
		</link>
		<link name="${prefix}link_2">
			<visual>
				<origin xyz="0 0 0" rpy="0 0 0"/>
				<geometry>
					<mesh filename="package://fanuc_config/meshes/m430ia2f/visual/link_2.stl"/>
				</geometry>
				<material name="">
					<color rgba="0.89804 0.89804 0.89804 1"/>
				</material>
			</visual>
			<collision>
				<origin xyz="0 0 0" rpy="0 0 0"/>
				<geometry>
					<mesh filename="package://fanuc_config/meshes/m430ia2f/collision/link_2.stl"/>
				</geometry>
			</collision>
		</link>
		<link name="${prefix}link_3">
			<visual>
				<!-- coordinate origin for link_3 is not at mate centre, -->
				<!-- so compensate (53mm dZ between link_3-link_2 mate -->
				<!-- and coordinate origin) -->
				<!-- origin xyz="0 0 0" rpy="0 0 0"/ -->
				<origin xyz="0 0 0.053" rpy="0 0 0"/>
				<geometry>
					<mesh filename="package://fanuc_config/meshes/m430ia2f/visual/link_3.stl"/>
				</geometry>
				<material name="">
					<color rgba="0.89804 0.89804 0.89804 1"/>
				</material>
			</visual>
			<collision>
				<!-- see earlier comment -->
				<!-- origin xyz="0 0 0" rpy="0 0 0"/ -->
				<origin xyz="0 0 0.053" rpy="0 0 0"/>
				<geometry>
					<mesh filename="package://fanuc_config/meshes/m430ia2f/collision/link_3.stl"/>
				</geometry>
			</collision>
		</link>
		<link name="${prefix}link_4">
			<visual>
				<origin xyz="0 0 0" rpy="0 0 0"/>
				<geometry>
					<mesh filename="package://fanuc_config/meshes/m430ia2f/visual/link_4.stl"/>
				</geometry>
				<material name="">
					<color rgba="0.89804 0.89804 0.89804 1"/>
				</material>
			</visual>
			<collision>
				<origin xyz="0 0 0" rpy="0 0 0"/>
				<geometry>
					<mesh filename="package://fanuc_config/meshes/m430ia2f/collision/link_4.stl"/>
				</geometry>
			</collision>
		</link>
		<link name="${prefix}link_5">
			<visual>
				<origin xyz="0 0 0" rpy="0 0 0"/>
				<geometry>
					<mesh filename="package://fanuc_config/meshes/m430ia2f/visual/link_5.stl"/>
				</geometry>
				<material name="">
					<color rgba="0.75294 0.75294 0.75294 1"/>
				</material>
			</visual>
			<collision>
				<origin xyz="0 0 0" rpy="0 0 0"/>
				<geometry>
					<mesh filename="package://fanuc_config/meshes/m430ia2f/collision/link_5.stl"/>
				</geometry>
			</collision>
		</link>
		<link name="${prefix}tool0"/>


		<!-- joints -->
		<joint name="${prefix}joint_1" type="revolute">
			<origin xyz="0 0 0.44" rpy="0 0 0"/>
			<parent link="${prefix}base_link"/>
			<child link="${prefix}link_1"/>
			<axis xyz="0 0 1"/>
			<limit lower="-3.1415" upper="3.1415" effort="0" velocity="5.24"/>
		</joint>
		<joint name="${prefix}joint_2" type="revolute">
			<origin xyz="0 0.171 0" rpy="0 0 0"/>
			<parent link="${prefix}link_1"/>
			<child link="${prefix}link_2"/>
			<axis xyz="0 1 0"/>
			<limit lower="-2.01" upper="2.01" effort="0" velocity="5.59"/>
		</joint>
		<joint name="${prefix}joint_3" type="revolute">
			<!-- see earlier comment -->
			<!-- origin xyz="0 -0.171 0.403" rpy="0 0 0"/ -->
			<origin xyz="0 -0.171 0.35" rpy="0 0 0"/>
			<parent link="${prefix}link_2"/>
			<child link="${prefix}link_3"/>
			<axis xyz="0 1 0"/>
			<limit lower="-3.34" upper="3.34" effort="0" velocity="5.59"/>
		</joint>
		<joint name="${prefix}joint_4" type="revolute">
			<!-- see earlier comment -->
			<!-- origin xyz="0 -0.06 0.497" rpy="0 0 0"/ -->
			<origin xyz="0 -0.06 0.55" rpy="0 0 0"/>
			<parent link="${prefix}link_3"/>
			<child link="${prefix}link_4"/>
			<axis xyz="0 1 0"/>
			<limit lower="-2.62" upper="2.62" effort="0" velocity="6.28"/>
		</joint>
		<joint name="${prefix}joint_5" type="revolute">
			<origin xyz="0 -0.035 0.065" rpy="0 0 0"/>
			<parent link="${prefix}link_4"/>
			<child link="${prefix}link_5"/>
			<axis xyz="0 0 1"/>
			<limit lower="-4.71" upper="4.71" effort="0" velocity="20.94"/>
		</joint>
		<joint name="${prefix}joint_5-tool0" type="fixed">
			<parent link="${prefix}link_5"/>
			<child link="${prefix}tool0"/>
			<origin xyz="0 0 0" rpy="0 0 0"/>
		</joint>

	</xacro:macro>
</robot>
