<?xml version="1.0"?>

<robot name="workcell" xmlns:xacro="http://ros.org/wiki/xacro">
  <link name="world"/>

  <!-- Include Robot definition here -->
  <!--   - don't forget joint to connect world_frame to robot's base_link -->
  <xacro:include filename="$(find abb_irb2400_support)/urdf/irb2400_macro.xacro"/>
  <xacro:abb_irb2400 prefix=""/>
  <joint name="world_to_robot" type="fixed">
    <parent link="world"/>
    <child link="base_link"/>
    <origin xyz="0 0 0" rpy="0 0 0"/>
  </joint>

  <!-- Include Workpiece definition here -->
  <link name="workpiece">
    <visual>
      <geometry>
        <box size="1.0 1.0 0.5"/>
      </geometry>
      <origin xyz="0 0 0.25"/>
    </visual>
  </link>
  <joint name="world_to_workpiece" type="fixed">
    <parent link="world"/>
    <child link="workpiece"/>
    <origin xyz="1.0 0 0.0" rpy="0 0 0"/>
  </joint>

  <!-- Include Gripper definition here -->
  <!--    - connect gripper to robot tool0 frame -->
  <link name="gripper">
    <visual>
      <geometry>
        <mesh filename="package://lesson_xacro/meshes/gripper.STL"/>
      </geometry>
      <origin xyz="0 0 0" rpy="0 0 0"/>
      <material name="gray">
        <color rgba="0.8 0.8 0.8 1.0"/>
      </material>
    </visual>
  </link>
  <joint name="tool_to_gripper" type="fixed">
    <parent link="tool0"/>
    <child link="gripper"/>
    <origin xyz="0 0 0" rpy="0 0 0"/>
  </joint>

  <!-- Include extra pieces here -->
  <link name="rail">
    <visual>
      <geometry>
        <box size="0.5 5.0 0.5"/>
      </geometry>
      <origin xyz="0 0 0.25" rpy="0 0 0"/>
      <material name="dark_gray">
        <color rgba="0.2 0.2 0.2 1.0"/>
      </material>
    </visual>
  </link>
  <joint name="world_to_rail" type="fixed">
    <parent link="world"/>
    <child link="rail"/>
    <origin xyz="2.0 0 0.0" rpy="0 0 0"/>
  </joint>

  <xacro:include filename="$(find motoman_config)/cfg/sia20d_mesh_macro.xacro"/>
  <xacro:sia20d_mesh prefix="robot2_"/>
  <joint name="rail_to_robot2" type="prismatic">
    <parent link="rail"/>
    <child link="robot2_base_link"/>
    <axis xyz="0 1 0"/>
    <origin xyz="0 0 0.5" rpy="0 0 3.14"/>
    <limit lower="-2.5" upper="2.5" effort="0" velocity="1.0"/>
  </joint>
</robot>

