<?xml version="1.0" ?>
<!-- =================================================================================== -->
<!-- |    This document was autogenerated by xacro from urdf/ur5_workspace.xacro       | -->
<!-- |    EDITING THIS FILE BY HAND IS NOT RECOMMENDED                                 | -->
<!-- =================================================================================== -->
<robot name="ur5_workspace" xmlns:controller="http://playerstage.sourceforge.net/gazebo/xmlschema/#controller" xmlns:interface="http://playerstage.sourceforge.net/gazebo/xmlschema/#interface" xmlns:sensor="http://playerstage.sourceforge.net/gazebo/xmlschema/#sensor" xmlns:xacro="http://ros.org/wiki/xacro">
  <gazebo>
    <controller:gazebo_ros_controller_manager name="gazebo_ros_controller_manager" plugin="libgazebo_ros_controller_manager.so">
      <alwaysOn>true</alwaysOn>
      <updateRate>1000.0</updateRate>
      <interface:audio name="gazebo_ros_controller_manager_dummy_iface"/>
    </controller:gazebo_ros_controller_manager>
    <controller:gazebo_ros_power_monitor name="gazebo_ros_power_monitor_controller" plugin="libgazebo_ros_power_monitor.so">
      <alwaysOn>true</alwaysOn>
      <updateRate>1.0</updateRate>
      <timeout>5</timeout>
      <interface:audio name="power_monitor_dummy_interface"/>
      <powerStateTopic>power_state</powerStateTopic>
      <powerStateRate>10.0</powerStateRate>
      <fullChargeCapacity>87.78</fullChargeCapacity>
      <dischargeRate>-474</dischargeRate>
      <chargeRate>525</chargeRate>
      <dischargeVoltage>15.52</dischargeVoltage>
      <chargeVoltage>16.41</chargeVoltage>
    </controller:gazebo_ros_power_monitor>
  </gazebo>
  <material name="yellow_transparent">
    <color rgba="0 1 1 0.4"/>
  </material>
  <material name="orange_transparent">
    <color rgba="1 0.5 0 0.4"/>
  </material>
  <material name="gray_transparent">
    <color rgba="0.6 0.6 0.6 0.4"/>
  </material>
  <material name="blue_transparent">
    <color rgba="0 0.8 1 0.4"/>
  </material>
  <link name="world_frame"/>
  <!-- property list -->
  <!-- instantiating arm and gripper -->
  <link name="base_link">
    <visual>
      <geometry>
        <mesh filename="package://ur5_description/meshes/Base.dae"/>
      </geometry>
      <origin rpy="0.0 0.0 2.3561944875" xyz="0.0 0.0 0.003"/>
    </visual>
    <inertial>
      <mass value="4.0"/>
      <inertia ixx="1.0" ixy="0.0" ixz="0.0" iyy="1.0" iyz="0.0" izz="1.0"/>
    </inertial>
  </link>
  <joint name="shoulder_pan_joint" type="revolute">
    <parent link="base_link"/>
    <child link="shoulder_link"/>
    <origin rpy="0.0 0.0 0.0" xyz="0.0 0.0 0.089159"/>
    <axis xyz="0.0 0.0 1.0"/>
    <limit effort="10.0" lower="-2.3561944875" upper="2.3561944875" velocity="3.14159265"/>
    <dynamics damping="10" friction="0.1"/>
  </joint>
  <link name="shoulder_link">
    <visual>
      <geometry>
        <mesh filename="package://ur5_description/meshes/Shoulder.dae"/>
      </geometry>
    </visual>
    <collision>
      <geometry>
        <cylinder length="0.16" radius="0.06"/>
      </geometry>
      <origin rpy="0.0 0.0 0.0" xyz="0.0 0.0 -0.009159"/>
    </collision>
    <inertial>
      <mass value="3.7"/>
      <inertia ixx="1.0" ixy="0.0" ixz="0.0" iyy="1.0" iyz="0.0" izz="1.0"/>
      <origin rpy="0.0 0.0 0.0" xyz="0.0 0.00193 -0.02561"/>
    </inertial>
  </link>
  <joint name="shoulder_lift_joint" type="revolute">
    <parent link="shoulder_link"/>
    <child link="upper_arm_link"/>
    <origin rpy="0.0 1.570796325 0.0" xyz="0.0 0.13585 0.0"/>
    <axis xyz="0.0 1.0 0.0"/>
    <limit effort="10.0" lower="-3.14159265" upper="3.14159265" velocity="3.14159265"/>
    <dynamics damping="10" friction="0.1"/>
  </joint>
  <link name="upper_arm_link">
    <visual>
      <geometry>
        <mesh filename="package://ur5_description/meshes/UpperArm.dae"/>
      </geometry>
      <origin rpy="0.0 0.0 0.0" xyz="0.0 0.0 0.0"/>
    </visual>
    <collision>
      <geometry>
        <cylinder length="0.425" radius="0.054"/>
      </geometry>
      <origin rpy="0.0 0.0 0.0" xyz="0.0 0.0 0.2125"/>
    </collision>
    <inertial>
      <mass value="8.393"/>
      <inertia ixx="1.0" ixy="0.0" ixz="0.0" iyy="1.0" iyz="0.0" izz="1.0"/>
      <origin rpy="0.0 0.0 0.0" xyz="0.0 -0.024201 0.2125"/>
    </inertial>
  </link>
  <joint name="elbow_joint" type="revolute">
    <parent link="upper_arm_link"/>
    <child link="forearm_link"/>
    <origin rpy="0.0 0.0 0.0" xyz="0.0 -0.1197 0.425"/>
    <axis xyz="0.0 1.0 0.0"/>
    <limit effort="10.0" lower="-0.62831853" upper="2.827433385" velocity="3.14159265"/>
    <dynamics damping="10" friction="0.1"/>
  </joint>
  <link name="forearm_link">
    <visual>
      <geometry>
        <mesh filename="package://ur5_description/meshes/Forearm.dae"/>
      </geometry>
    </visual>
    <collision>
      <geometry>
        <cylinder length="0.39225" radius="0.04"/>
      </geometry>
      <origin rpy="0.0 0.0 0.0" xyz="0.0 0.0 0.196125"/>
    </collision>
    <inertial>
      <mass value="2.275"/>
      <origin rpy="0.0 0.0 0.0" xyz="0.0 0.0265 0.11993"/>
      <inertia ixx="1.0" ixy="0.0" ixz="0.0" iyy="1.0" iyz="0.0" izz="1.0"/>
    </inertial>
  </link>
  <joint name="wrist_1_joint" type="revolute">
    <parent link="forearm_link"/>
    <child link="wrist_1_link"/>
    <origin rpy="0.0 1.570796325 0.0" xyz="0.0 0.0 0.39225"/>
    <axis xyz="0.0 1.0 0.0"/>
    <limit effort="10.0" lower="-3.14159265" upper="0.0314159265" velocity="3.14159265"/>
    <dynamics damping="10" friction="0.1"/>
  </joint>
  <link name="wrist_1_link">
    <visual>
      <geometry>
        <mesh filename="package://ur5_description/meshes/Wrist1.dae"/>
      </geometry>
      <origin rpy="0.0 1.570796325 0.0" xyz="0.0 0.093 0.0"/>
    </visual>
    <collision>
      <geometry>
        <cylinder length="0.1488" radius="0.045"/>
      </geometry>
      <origin rpy="-1.570796325 0.0 0.0" xyz="0.0 0.02325 0.0"/>
    </collision>
    <inertial>
      <mass value="1.219"/>
      <origin rpy="0.0 0.0 0.0" xyz="0.0 0.110949 0.01634"/>
      <inertia ixx="1.0" ixy="0.0" ixz="0.0" iyy="1.0" iyz="0.0" izz="1.0"/>
    </inertial>
  </link>
  <joint name="wrist_2_joint" type="revolute">
    <parent link="wrist_1_link"/>
    <child link="wrist_2_link"/>
    <origin rpy="0.0 0.0 0.0" xyz="0.0 0.093 0.0"/>
    <axis xyz="0.0 0.0 1.0"/>
    <limit effort="10.0" lower="-3.14159265" upper="3.14159265" velocity="3.14159265"/>
    <dynamics damping="10" friction="0.1"/>
  </joint>
  <link name="wrist_2_link">
    <visual>
      <geometry>
        <mesh filename="package://ur5_description/meshes/Wrist2.dae"/>
      </geometry>
      <origin rpy="0.0 0.0 0.0" xyz="0.0 0.0 0.09465"/>
    </visual>
    <collision>
      <geometry>
        <cylinder length="0.15144" radius="0.045"/>
      </geometry>
      <origin rpy="0.0 0.0 0.0" xyz="0.0 0.0 0.0236625"/>
    </collision>
    <inertial>
      <mass value="1.219"/>
      <origin rpy="0.0 0.0 0.0" xyz="0.0 0.0018 0.11099"/>
      <inertia ixx="1.0" ixy="0.0" ixz="0.0" iyy="1.0" iyz="0.0" izz="1.0"/>
    </inertial>
  </link>
  <joint name="wrist_3_joint" type="revolute">
    <parent link="wrist_2_link"/>
    <child link="wrist_3_link"/>
    <origin rpy="0.0 0.0 0.0" xyz="0.0 0.0 0.09465"/>
    <axis xyz="0.0 1.0 0.0"/>
    <limit effort="10.0" lower="-4.712388975" upper="4.712388975" velocity="3.14159265"/>
    <dynamics damping="10" friction="0.1"/>
  </joint>
  <link name="wrist_3_link">
    <visual>
      <geometry>
        <mesh filename="package://ur5_description/meshes/Wrist3.dae"/>
      </geometry>
    </visual>
    <collision>
      <geometry>
        <cylinder length="0.135795" radius="0.045"/>
      </geometry>
      <origin rpy="-1.570796325 0.0 0.0" xyz="0.0 0.012345 0.0"/>
    </collision>
    <inertial>
      <mass value="0.1879"/>
      <origin rpy="0.0 0.0 0.0" xyz="0.0 0.001159 0.0"/>
      <inertia ixx="1.0" ixy="0.0" ixz="0.0" iyy="1.0" iyz="0.0" izz="1.0"/>
    </inertial>
  </link>
  <joint name="ee_fixed_joint" type="fixed">
    <parent link="wrist_3_link"/>
    <child link="ee_link"/>
    <origin rpy="0.0 0.0 1.570796325" xyz="0.0 0.0823 0.0"/>
  </joint>
  <link name="ee_link"/>
  <transmission name="shoulder_pan_trans" type="pr2_mechanism_model/SimpleTransmission">
    <actuator name="shoulder_pan_motor"/>
    <joint name="shoulder_pan_joint"/>
    <mechanicalReduction>1</mechanicalReduction>
  </transmission>
  <transmission name="shoulder_lift_trans" type="pr2_mechanism_model/SimpleTransmission">
    <actuator name="shoulder_lift_motor"/>
    <joint name="shoulder_lift_joint"/>
    <mechanicalReduction>1</mechanicalReduction>
  </transmission>
  <transmission name="elbow_trans" type="pr2_mechanism_model/SimpleTransmission">
    <actuator name="elbow_motor"/>
    <joint name="elbow_joint"/>
    <mechanicalReduction>1</mechanicalReduction>
  </transmission>
  <transmission name="wrist_1_trans" type="pr2_mechanism_model/SimpleTransmission">
    <actuator name="wrist_1_motor"/>
    <joint name="wrist_1_joint"/>
    <mechanicalReduction>1</mechanicalReduction>
  </transmission>
  <transmission name="wrist_2_trans" type="pr2_mechanism_model/SimpleTransmission">
    <actuator name="wrist_2_motor"/>
    <joint name="wrist_2_joint"/>
    <mechanicalReduction>1</mechanicalReduction>
  </transmission>
  <transmission name="wrist_3_trans" type="pr2_mechanism_model/SimpleTransmission">
    <actuator name="wrist_3_motor"/>
    <joint name="wrist_3_joint"/>
    <mechanicalReduction>1</mechanicalReduction>
  </transmission>
  <gazebo reference="universal_robot">
    <material>Gazebo/Blue</material>
  </gazebo>
  <link name="gripper_frame"/>
  <link name="gripper_body">
    <visual>
      <!--origin xyz="0 0.036 -0.0473" rpy="0 0 0"/-->
      <!--geometry>
					<box size="${gripper_length} ${gripper_width} ${gripper_height}"/>
				</geometry-->
      <origin rpy="0 0 0" xyz="0 0 -0.048"/>
      <geometry>
        <mesh filename="package://robot_config/meshes/vacuum_gripper_single_suction_cup.STL"/>
      </geometry>
      <material name="silver">
        <color rgba="0.8 0.8 0.8 1"/>
      </material>
    </visual>
    <collision>
      <geometry>
        <box size="0.044 0.088 0.0946"/>
      </geometry>
      <material name="another_blue2">
        <color rgba="0.38 0.54 0.83 1"/>
      </material>
    </collision>
  </link>
  <link name="tcp_frame"/>
  <joint name="gripper_to_palm" type="fixed">
    <parent link="gripper_frame"/>
    <child link="gripper_body"/>
    <origin rpy="0 0 0" xyz="0 0 0.0473"/>
  </joint>
  <joint name="gripper_to_tcp" type="fixed">
    <parent link="gripper_frame"/>
    <child link="tcp_frame"/>
    <origin rpy="0 0 0" xyz=" 0 0.022 0.13"/>
  </joint>
  <!-- instantiating workcell definitions -->
  <link name="table_base2">
    <visual>
      <origin rpy="0 0 0" xyz="0 0 -0.5"/>
      <geometry>
        <box size="1.3875 2.22 1"/>
      </geometry>
      <material name="orange_transparent"/>
    </visual>
    <collision>
      <origin rpy="0 0 0" xyz="0 0 -0.5"/>
      <geometry>
        <box size="1.3875 2.22 1"/>
      </geometry>
      <material name="blue_transparent"/>
    </collision>
  </link>
  <joint name="workcell_to_table_base2" type="fixed">
    <parent link="world_frame"/>
    <child link="table_base2"/>
    <origin rpy="0 0 0" xyz="-0.69375 0 0"/>
  </joint>
  <link name="front_wall2">
    <visual>
      <geometry>
        <box size="0.1 2.22 1"/>
      </geometry>
      <material name="gray_transparent"/>
    </visual>
    <collision>
      <geometry>
        <box size="0.1 2.22 1"/>
      </geometry>
      <material name="blue_transparent"/>
    </collision>
  </link>
  <joint name="world_frame_to_front_wall2" type="fixed">
    <parent link="world_frame"/>
    <child link="front_wall2"/>
    <origin rpy="0 0 0" xyz="-1.3375 0 0.5"/>
  </joint>
  <link name="left_wall2">
    <visual>
      <geometry>
        <box size="1.384 0.1 1"/>
      </geometry>
      <material name="gray_transparent"/>
    </visual>
    <collision>
      <geometry>
        <box size="1.384 0.1 1"/>
      </geometry>
      <material name="blue_transparent"/>
    </collision>
  </link>
  <joint name="world_frame_to_left_wall2" type="fixed">
    <parent link="world_frame"/>
    <child link="left_wall2"/>
    <origin rpy="0 0 0" xyz="-0.601 1.06 0.5"/>
  </joint>
  <link name="right_wall2">
    <visual>
      <geometry>
        <box size="1.384 0.1 1"/>
      </geometry>
      <material name="gray_transparent"/>
    </visual>
    <collision>
      <geometry>
        <box size="1.384 0.1 1"/>
      </geometry>
      <material name="blue_transparent"/>
    </collision>
  </link>
  <joint name="world_frame_to_right_wall2" type="fixed">
    <parent link="world_frame"/>
    <child link="right_wall2"/>
    <origin rpy="0 0 0" xyz="-0.601 -1.06 0.5"/>
  </joint>
  <link name="cover_part1">
    <visual>
      <geometry>
        <box size="0.229 0.508 0.14"/>
      </geometry>
      <material name="gray_transparent"/>
    </visual>
    <collision>
      <geometry>
        <box size="0.229 0.508 0.14"/>
      </geometry>
      <material name="blue_transparent"/>
    </collision>
  </link>
  <joint name="world_frame_to_cover_part1" type="fixed">
    <parent link="world_frame"/>
    <child link="cover_part1"/>
    <origin rpy="0 0 0" xyz="-0.042 -0.081 0.07"/>
  </joint>
  <link name="cover_part2">
    <visual>
      <geometry>
        <box size="0.121 0.26 0.14"/>
      </geometry>
      <material name="gray_transparent"/>
    </visual>
    <collision>
      <geometry>
        <box size="0.121 0.26 0.14"/>
      </geometry>
      <material name="blue_transparent"/>
    </collision>
  </link>
  <joint name="world_frame_to_cover_part2" type="fixed">
    <parent link="world_frame"/>
    <child link="cover_part2"/>
    <origin rpy="0 0 0" xyz="-0.012 -0.465 0.07"/>
  </joint>
  <!-- end of workcell definitions -->
  <!-- arm-workcell link definitions -->
  <link name="ur5_stand">
    <visual>
      <geometry>
        <cylinder length="0.2" radius="0.0735"/>
      </geometry>
      <material name="orange_transparent"/>
    </visual>
    <collision>
      <geometry>
        <cylinder length="0.2" radius="0.0735"/>
      </geometry>
      <material name="blue_transparent"/>
    </collision>
  </link>
  <!-- instantiating sensor definitions -->
  <material name="color_b">
    <color rgba="0 0.8 1 0.4"/>
  </material>
  <material name="color_a">
    <color rgba="0.8 0.2 1 0.2"/>
  </material>
  <material name="silver">
    <color rgba="0.6 0.6 0.6 1"/>
  </material>
  <link name="kinect_link">
    <collision>
      <material name="color_a"/>
      <geometry>
        <box size="0.36 0.28 0.22"/>
      </geometry>
    </collision>
  </link>
  <link name="kinect_keepout">
    <!--collision>
				<material name="${prefix}color_b"/>
				<geometry>
					<box size="0.2 0.32 ${z_val + 0.08}"/>
				</geometry>
			</collision-->
  </link>
  <link name="kinect_frame">
    <visual>
      <origin rpy="0 0 0" xyz="0 0 0"/>
      <geometry>
        <box size="0.064 0.28 0.04"/>
      </geometry>
      <material name="silver"/>
    </visual>
    <collision>
      <origin rpy="0 0 0" xyz="0 0 0"/>
      <geometry>
        <box size="0.064 0.28 0.04"/>
      </geometry>
    </collision>
  </link>
  <link name="kinect_ir_link">
    <visual>
      <origin rpy="0 0 0" xyz="0 0 0"/>
      <geometry>
        <sphere radius="0.0005"/>
      </geometry>
    </visual>
  </link>
  <link name="kinect_rgb_link">
    <visual>
      <origin rpy="0 0 0" xyz="0 0 0"/>
      <geometry>
        <sphere radius="0.0005"/>
      </geometry>
    </visual>
  </link>
  <link name="kinect_ir_optical_frame"/>
  <link name="kinect_rgb_optical_frame"/>
  <joint name="kinect_frame_joint" type="fixed">
    <parent link="kinect_link"/>
    <child link="kinect_frame"/>
    <origin rpy="0 0 0" xyz="0 0 0"/>
  </joint>
  <joint name="kinect_ir_joint" type="fixed">
    <parent link="kinect_frame"/>
    <child link="kinect_ir_link"/>
    <origin rpy="0 0 0" xyz="0 0 0"/>
  </joint>
  <joint name="kinect_ir_optical_frame_joint" type="fixed">
    <parent link="kinect_ir_link"/>
    <child link="kinect_ir_optical_frame"/>
    <origin rpy="-1.57 0 -1.57" xyz="0 0 0"/>
  </joint>
  <joint name="kinect_rgb_joint" type="fixed">
    <parent link="kinect_ir_link"/>
    <child link="kinect_rgb_link"/>
    <origin rpy="0 0 0" xyz="0 -0.03 0"/>
  </joint>
  <joint name="kinect_rgb_optical_frame_joint" type="fixed">
    <parent link="kinect_rgb_link"/>
    <child link="kinect_rgb_optical_frame"/>
    <origin rpy="-1.57 0 -1.57" xyz="0 0 0"/>
  </joint>
  <joint name="ur5_stand_to_kinect_link" type="fixed">
    <parent link="ur5_stand"/>
    <child link="kinect_link"/>
    <origin rpy="0.019 1.145 0.035" xyz="-0.981 0.19 1.015"/>
  </joint>
  <joint name="ur5_stand_to_kinect_keepout" type="fixed">
    <parent link="ur5_stand"/>
    <child link="kinect_keepout"/>
    <origin rpy="0 0 0.035" xyz="-0.981 0.19 0.5475"/>
  </joint>
  <!-- end of sensor definitions -->
  <joint name="world_to_stand" type="fixed">
    <parent link="world_frame"/>
    <child link="ur5_stand"/>
    <origin xyz="-0.238 0 0.1"/>
  </joint>
  <!-- end of arm-workcell link definitions -->
  <!-- arm-workcell joint definitions -->
  <joint name="stand_to_base" type="fixed">
    <parent link="ur5_stand"/>
    <child link="base_link"/>
    <origin rpy="0 0 2.355" xyz="0 0 0.1"/>
  </joint>
  <!-- end of arm workcell joint definitions-->
  <!-- arm-gripper coupling joint definitions -->
  <joint name="to_gripper" type="fixed">
    <parent link="ee_link"/>
    <child link="gripper_frame"/>
    <origin rpy="-1.57 0 -1.57" xyz="0 0 0"/>
    <!-- 0 1.57 0 -->
  </joint>
  <!-- end of arm-gripper coupling joint definitions -->
</robot>

