<?xml version="1.0" ?>
<!-- =================================================================================== -->
<!-- |    This document was autogenerated by xacro from motoman_workspace.xacro        | -->
<!-- |    EDITING THIS FILE BY HAND IS NOT RECOMMENDED                                 | -->
<!-- =================================================================================== -->
<robot name="motoman_mh5" xmlns:xacro="http://ros.org/wiki/xacro">
  <link name="base_link">
    <visual>
      <geometry>
        <mesh filename="package://motoman_mh5_support/meshes/mh5/visual/MH5_BASE_AXIS.stl"/>
      </geometry>
      <material name="blue">
        <color rgba="0 0 1 1"/>
      </material>
    </visual>
    <collision>
      <geometry>
        <mesh filename="package://motoman_mh5_support/meshes/mh5/collision/MH5_BASE_AXIS.stl"/>
      </geometry>
      <material name="yellow">
        <color rgba="0 1 1 1"/>
      </material>
    </collision>
  </link>
  <link name="link_s">
    <visual>
      <geometry>
        <mesh filename="package://motoman_mh5_support/meshes/mh5/visual/MH5_S_AXIS.stl"/>
      </geometry>
      <material name="silver">
        <color rgba="0.8 0.8 0.8 1"/>
      </material>
    </visual>
    <collision>
      <geometry>
        <mesh filename="package://motoman_mh5_support/meshes/mh5/collision/MH5_S_AXIS.stl"/>
      </geometry>
      <material name="yellow"/>
    </collision>
  </link>
  <link name="link_l">
    <visual>
      <!-- <origin rpy="1.57 3.1416 0" xyz="0 0 0"/> -->
      <geometry>
        <mesh filename="package://motoman_mh5_support/meshes/mh5/visual/MH5_L_AXIS.stl"/>
      </geometry>
      <material name="blue"/>
    </visual>
    <collision>
      <!-- <origin rpy="1.57 3.1416 0" xyz="0 0 0"/> -->
      <geometry>
        <mesh filename="package://motoman_mh5_support/meshes/mh5/collision/MH5_L_AXIS.stl"/>
      </geometry>
      <material name="yellow"/>
    </collision>
  </link>
  <link name="link_u">
    <visual>
      <!-- <origin rpy="1.57 -3.1415 0" xyz="0 0 0"/> -->
      <geometry>
        <mesh filename="package://motoman_mh5_support/meshes/mh5/visual/MH5_U_AXIS.stl"/>
      </geometry>
      <material name="blue"/>
    </visual>
    <collision>
      <!-- <origin rpy="1.57 -3.1415 0" xyz="0 0 0"/> -->
      <geometry>
        <mesh filename="package://motoman_mh5_support/meshes/mh5/collision/MH5_U_AXIS.stl"/>
      </geometry>
      <material name="yellow"/>
    </collision>
  </link>
  <link name="link_r">
    <visual>
      <!-- <origin rpy="0 0 3.1416" xyz="0 0 0"/> -->
      <geometry>
        <mesh filename="package://motoman_mh5_support/meshes/mh5/visual/MH5_R_AXIS.stl"/>
      </geometry>
      <material name="silver"/>
    </visual>
    <collision>
      <!-- <origin rpy="0 0 3.1416" xyz="0 0 0"/> -->
      <geometry>
        <mesh filename="package://motoman_mh5_support/meshes/mh5/collision/MH5_R_AXIS.stl"/>
      </geometry>
      <material name="yellow"/>
    </collision>
  </link>
  <link name="link_b">
    <visual>
      <!-- <origin rpy="-1.57 0 3.1416" xyz="0 0 0"/> -->
      <geometry>
        <mesh filename="package://motoman_mh5_support/meshes/mh5/visual/MH5_B_AXIS.stl"/>
      </geometry>
      <material name="blue"/>
    </visual>
    <collision>
      <!-- <origin rpy="-1.57 0 3.1416" xyz="0 0 0"/> -->
      <geometry>
        <mesh filename="package://motoman_mh5_support/meshes/mh5/collision/MH5_B_AXIS.stl"/>
      </geometry>
      <material name="yellow"/>
    </collision>
  </link>
  <link name="link_t">
    <visual>
      <geometry>
        <mesh filename="package://motoman_mh5_support/meshes/mh5/visual/MH5_T_AXIS.stl"/>
      </geometry>
      <material name="silver"/>
    </visual>
    <collision>
      <geometry>
        <mesh filename="package://motoman_mh5_support/meshes/mh5/collision/MH5_T_AXIS.stl"/>
      </geometry>
      <material name="yellow"/>
    </collision>
  </link>
  <joint name="joint_s" type="revolute">
    <parent link="base_link"/>
    <child link="link_s"/>
    <origin rpy="0 0 0" xyz="0 0 0.1990"/>
    <axis xyz="0 0 1"/>
    <limit effort="100" lower="-2.9671" upper="2.9671" velocity="2.96"/>
  </joint>
  <joint name="joint_l" type="revolute">
    <parent link="link_s"/>
    <child link="link_l"/>
    <origin rpy="0 0 0" xyz="0.0880 0 0.1310"/>
    <axis xyz="0 1 0"/>
    <limit effort="100" lower="-1.1345" upper="2.6180" velocity="2.96"/>
  </joint>
  <joint name="joint_u" type="revolute">
    <parent link="link_l"/>
    <child link="link_u"/>
    <origin rpy="0 0 0" xyz="0 0 0.3100"/>
    <axis xyz="0 -1 0"/>
    <limit effort="100" lower="-2.3736" upper="4.4506" velocity="2.96"/>
  </joint>
  <joint name="joint_r" type="revolute">
    <parent link="link_u"/>
    <child link="link_r"/>
    <origin rpy="0 0 0" xyz="0.0715 0 0.0399"/>
    <axis xyz="-1 0 0"/>
    <limit effort="100" lower="-3.3161" upper="3.3161" velocity="3.48"/>
  </joint>
  <joint name="joint_b" type="revolute">
    <parent link="link_r"/>
    <child link="link_b"/>
    <origin rpy="0 0 0" xyz="0.2335 0 0"/>
    <axis xyz="0 -1 0"/>
    <limit effort="100" lower="-2.1817" upper="2.1817" velocity="3.48"/>
  </joint>
  <joint name="joint_t" type="revolute">
    <parent link="link_b"/>
    <child link="link_t"/>
    <origin rpy="0 0 0" xyz="0.0510 0 0"/>
    <axis xyz="-1 0 0"/>
    <limit effort="100" lower="-6.2831" upper="6.2831" velocity="6.97"/>
  </joint>
  <material name="yellow_transparent">
    <color rgba="0 1 1 0.4"/>
  </material>
  <material name="orange_transparent">
    <color rgba="1 0.5 0 0.4"/>
  </material>
  <material name="gray_transparent">
    <color rgba="0.6 0.6 0.6 0.4"/>
  </material>
  <material name="blue_transparent">
    <color rgba="0 0.8 1 0.4"/>
  </material>
  <link name="world_frame"/>
  <!-- property list -->
  <!-- instantiating arm and gripper -->
  <xacro:motoman_robot prefix=""/>
  <link name="gripper_frame"/>
  <link name="gripper_body">
    <visual>
      <!--origin xyz="0 0.036 -0.0473" rpy="0 0 0"/-->
      <!--geometry>
					<box size="${gripper_length} ${gripper_width} ${gripper_height}"/>
				</geometry-->
      <origin rpy="0 0 0" xyz="0 0 -0.048"/>
      <geometry>
        <mesh filename="package://robot_config/meshes/vacuum_gripper_single_suction_cup.STL"/>
      </geometry>
      <material name="silver">
        <color rgba="0.8 0.8 0.8 1"/>
      </material>
    </visual>
    <collision>
      <!--<origin xyz="0 0 0.03"/>-->
      <geometry>
        <box size="0.044 0.088 0.16"/>
      </geometry>
      <material name="another_blue2">
        <color rgba="0.38 0.54 0.83 1"/>
      </material>
    </collision>
  </link>
  <link name="tcp_frame">
    <visual>
      <geometry>
        <sphere radius="0.005"/>
      </geometry>
      <material name="white">
        <color rgba="1 1 1 0.5"/>
      </material>
    </visual>
    <collision>
      <geometry>
        <sphere radius="0.005"/>
      </geometry>
    </collision>
  </link>
  <joint name="gripper_to_palm" type="fixed">
    <parent link="gripper_frame"/>
    <child link="gripper_body"/>
    <origin rpy="0 0 0" xyz="0 0 0.0473"/>
  </joint>
  <joint name="gripper_to_tcp" type="fixed">
    <parent link="gripper_frame"/>
    <child link="tcp_frame"/>
    <origin rpy="0 0 0" xyz=" 0 0.022 0.13"/>
  </joint>
  <!-- instantiating workcell definitions -->
  <link name="table_base2">
    <visual>
      <origin rpy="0 0 0" xyz="0 0 -0.5"/>
      <geometry>
        <box size="1.3875 2.22 1"/>
      </geometry>
      <material name="orange_transparent"/>
    </visual>
    <collision>
      <origin rpy="0 0 0" xyz="0 0 -0.5"/>
      <geometry>
        <box size="1.3875 2.22 1"/>
      </geometry>
      <material name="blue_transparent"/>
    </collision>
  </link>
  <link name="roof2">
    <collision>
      <origin rpy="0 0 0" xyz="0 0 1"/>
      <geometry>
        <box size="1.3875 2.22 0.04"/>
      </geometry>
      <material name="blue_transparent"/>
    </collision>
  </link>
  <joint name="workcell_to_table_base2" type="fixed">
    <parent link="world_frame"/>
    <child link="table_base2"/>
    <origin rpy="0 0 0" xyz="-0.69375 0 0"/>
  </joint>
  <joint name="workcell_to_roof2" type="fixed">
    <parent link="world_frame"/>
    <child link="roof2"/>
    <origin rpy="0 0 0" xyz="-0.69375 0 0"/>
  </joint>
  <link name="front_wall2">
    <visual>
      <geometry>
        <box size="0.1 2.22 1"/>
      </geometry>
      <material name="gray_transparent"/>
    </visual>
    <collision>
      <geometry>
        <box size="0.1 2.22 1"/>
      </geometry>
      <material name="blue_transparent"/>
    </collision>
  </link>
  <joint name="world_frame_to_front_wall2" type="fixed">
    <parent link="world_frame"/>
    <child link="front_wall2"/>
    <origin rpy="0 0 0" xyz="-1.3375 0 0.5"/>
  </joint>
  <link name="back_wall2">
    <visual>
      <geometry>
        <box size="0.04 2.0 1"/>
      </geometry>
      <material name="gray_transparent"/>
    </visual>
    <collision>
      <geometry>
        <box size="0.04 2.0 1"/>
      </geometry>
      <material name="blue_transparent"/>
    </collision>
  </link>
  <joint name="world_frame_to_back_wall2" type="fixed">
    <parent link="world_frame"/>
    <child link="back_wall2"/>
    <origin rpy="0 0 0" xyz="0.2 0 0.5"/>
  </joint>
  <link name="left_wall2">
    <visual>
      <geometry>
        <box size="1.384 0.1 1"/>
      </geometry>
      <material name="gray_transparent"/>
    </visual>
    <collision>
      <geometry>
        <box size="1.384 0.1 1"/>
      </geometry>
      <material name="blue_transparent"/>
    </collision>
  </link>
  <joint name="world_frame_to_left_wall2" type="fixed">
    <parent link="world_frame"/>
    <child link="left_wall2"/>
    <origin rpy="0 0 0" xyz="-0.601 1.06 0.5"/>
  </joint>
  <link name="right_wall2">
    <visual>
      <geometry>
        <box size="1.384 0.1 1"/>
      </geometry>
      <material name="gray_transparent"/>
    </visual>
    <collision>
      <geometry>
        <box size="1.384 0.1 1"/>
      </geometry>
      <material name="blue_transparent"/>
    </collision>
  </link>
  <joint name="world_frame_to_right_wall2" type="fixed">
    <parent link="world_frame"/>
    <child link="right_wall2"/>
    <origin rpy="0 0 0" xyz="-0.601 -1.06 0.5"/>
  </joint>
  <link name="cover_part1">
    <visual>
      <geometry>
        <box size="0.229 0.508 0.14"/>
      </geometry>
      <material name="gray_transparent"/>
    </visual>
    <collision>
      <geometry>
        <box size="0.229 0.508 0.14"/>
      </geometry>
      <material name="blue_transparent"/>
    </collision>
  </link>
  <joint name="world_frame_to_cover_part1" type="fixed">
    <parent link="world_frame"/>
    <child link="cover_part1"/>
    <origin rpy="0 0 0" xyz="-0.042 -0.081 0.07"/>
  </joint>
  <link name="cover_part2">
    <visual>
      <geometry>
        <box size="0.121 0.26 0.14"/>
      </geometry>
      <material name="gray_transparent"/>
    </visual>
    <collision>
      <geometry>
        <box size="0.121 0.26 0.14"/>
      </geometry>
      <material name="blue_transparent"/>
    </collision>
  </link>
  <joint name="world_frame_to_cover_part2" type="fixed">
    <parent link="world_frame"/>
    <child link="cover_part2"/>
    <origin rpy="0 0 0" xyz="-0.012 -0.465 0.07"/>
  </joint>
  <!-- end of workcell definitions -->
  <!-- arm-workcell link definitions -->
  <link name="motoman_stand">
    <visual>
      <geometry>
        <cylinder length="0.2" radius="0.0735"/>
      </geometry>
      <material name="orange_transparent"/>
    </visual>
    <collision>
      <geometry>
        <cylinder length="0.2" radius="0.0735"/>
      </geometry>
      <material name="blue_transparent"/>
    </collision>
  </link>
  <!-- instantiating sensor definitions -->
  <material name="color_b">
    <color rgba="0 0.8 1 0.4"/>
  </material>
  <material name="color_a">
    <color rgba="0.8 0.2 1 0.2"/>
  </material>
  <material name="silver">
    <color rgba="0.6 0.6 0.6 1"/>
  </material>
  <link name="kinect_link">
    <collision>
      <material name="color_a"/>
      <geometry>
        <box size="0.36 0.28 0.22"/>
      </geometry>
    </collision>
  </link>
  <link name="kinect_keepout">
    <!--collision>
				<material name="${prefix}color_b"/>
				<geometry>
					<box size="0.2 0.32 ${z_val + 0.08}"/>
				</geometry>
			</collision-->
  </link>
  <link name="kinect_frame">
    <visual>
      <origin rpy="0 0 0" xyz="0 0 0"/>
      <geometry>
        <box size="0.064 0.28 0.04"/>
      </geometry>
      <material name="silver"/>
    </visual>
    <collision>
      <origin rpy="0 0 0" xyz="0 0 0"/>
      <geometry>
        <box size="0.064 0.28 0.04"/>
      </geometry>
    </collision>
  </link>
  <link name="kinect_ir_link">
    <visual>
      <origin rpy="0 0 0" xyz="0 0 0"/>
      <geometry>
        <sphere radius="0.0005"/>
      </geometry>
    </visual>
  </link>
  <link name="kinect_rgb_link">
    <visual>
      <origin rpy="0 0 0" xyz="0 0 0"/>
      <geometry>
        <sphere radius="0.0005"/>
      </geometry>
    </visual>
  </link>
  <link name="kinect_ir_optical_frame"/>
  <link name="kinect_rgb_optical_frame"/>
  <joint name="kinect_frame_joint" type="fixed">
    <parent link="kinect_link"/>
    <child link="kinect_frame"/>
    <origin rpy="0 0 0" xyz="0 0 0"/>
  </joint>
  <joint name="kinect_ir_joint" type="fixed">
    <parent link="kinect_frame"/>
    <child link="kinect_ir_link"/>
    <origin rpy="0 0 0" xyz="0 0 0"/>
  </joint>
  <joint name="kinect_ir_optical_frame_joint" type="fixed">
    <parent link="kinect_ir_link"/>
    <child link="kinect_ir_optical_frame"/>
    <origin rpy="-1.57 0 -1.57" xyz="0 0 0"/>
  </joint>
  <joint name="kinect_rgb_joint" type="fixed">
    <parent link="kinect_ir_link"/>
    <child link="kinect_rgb_link"/>
    <origin rpy="0 0 0" xyz="0 -0.03 0"/>
  </joint>
  <joint name="kinect_rgb_optical_frame_joint" type="fixed">
    <parent link="kinect_rgb_link"/>
    <child link="kinect_rgb_optical_frame"/>
    <origin rpy="-1.57 0 -1.57" xyz="0 0 0"/>
  </joint>
  <joint name="motoman_stand_to_kinect_link" type="fixed">
    <parent link="motoman_stand"/>
    <child link="kinect_link"/>
    <origin rpy="0.019 1.145 0.035" xyz="-0.981 0.19 1.015"/>
  </joint>
  <joint name="motoman_stand_to_kinect_keepout" type="fixed">
    <parent link="motoman_stand"/>
    <child link="kinect_keepout"/>
    <origin rpy="0 0 0.035" xyz="-0.981 0.19 0.5475"/>
  </joint>
  <!-- end of sensor definitions -->
  <joint name="world_to_stand" type="fixed">
    <parent link="world_frame"/>
    <child link="motoman_stand"/>
    <origin xyz="-0.238 0 0.1"/>
  </joint>
  <!-- end of arm-workcell link definitions -->
  <!-- arm-workcell joint definitions -->
  <joint name="stand_to_base" type="fixed">
    <parent link="motoman_stand"/>
    <child link="base_link"/>
    <origin rpy="0 0 2.355" xyz="0 0 0.1"/>
  </joint>
  <!-- end of arm workcell joint definitions-->
  <!-- arm-gripper coupling joint definitions -->
  <joint name="to_gripper" type="fixed">
    <parent link="link_t"/>
    <child link="gripper_frame"/>
    <origin rpy="-1.57 0 -1.57" xyz="0 0 0"/>
    <!-- 0 1.57 0 -->
  </joint>
  <!-- end of arm-gripper coupling joint definitions -->
</robot>
