<?xml version="1.0" ?>
<!-- =================================================================================== -->
<!-- |    This document was autogenerated by xacro from urdf/workcell.xacro            | -->
<!-- |    EDITING THIS FILE BY HAND IS NOT RECOMMENDED                                 | -->
<!-- =================================================================================== -->
<robot name="workcell" xmlns:xacro="http://ros.org/wiki/xacro">
  <link name="world_frame"/>
  <link name="base_link">
    <visual>
      <origin rpy="0 0 0" xyz="0 0 0"/>
      <geometry>
        <mesh filename="package://abb_common/meshes/irb_2400/visual/base_link.STL"/>
      </geometry>
      <material name="abb_orange">
        <color rgba="1 0.43 0 1"/>
      </material>
    </visual>
    <collision>
      <geometry>
        <mesh filename="package://abb_common/meshes/irb_2400/collision/base_link.STL"/>
      </geometry>
      <material name="yellow">
        <color rgba="0 1 1 1"/>
      </material>
    </collision>
  </link>
  <link name="link_1">
    <visual>
      <origin rpy="0 0 0" xyz="0 0 0"/>
      <geometry>
        <mesh filename="package://abb_common/meshes/irb_2400/visual/link_1.STL"/>
      </geometry>
      <material name="abb_orange"/>
    </visual>
    <collision>
      <origin rpy="0 0 0" xyz="0 0 0"/>
      <geometry>
        <mesh filename="package://abb_common/meshes/irb_2400/collision/link_1.STL"/>
      </geometry>
      <material name="yellow"/>
    </collision>
  </link>
  <link name="link_2">
    <visual>
      <origin rpy="0 0 0" xyz="0 0 0"/>
      <geometry>
        <mesh filename="package://abb_common/meshes/irb_2400/visual/link_2.STL"/>
      </geometry>
      <material name="abb_orange"/>
    </visual>
    <collision>
      <origin rpy="0 0 0" xyz="0 0 0"/>
      <geometry>
        <mesh filename="package://abb_common/meshes/irb_2400/collision/link_2_whole.STL"/>
      </geometry>
      <material name="yellow"/>
    </collision>
  </link>
  <link name="link_3">
    <visual>
      <origin rpy="0 0 0" xyz="0 0 0"/>
      <geometry>
        <mesh filename="package://abb_common/meshes/irb_2400/visual/link_3.STL"/>
      </geometry>
      <material name="abb_orange"/>
    </visual>
    <collision>
      <origin rpy="0 0 0" xyz="0 0 0"/>
      <geometry>
        <mesh filename="package://abb_common/meshes/irb_2400/collision/link_3.STL"/>
      </geometry>
      <material name="yellow"/>
    </collision>
  </link>
  <link name="link_4">
    <visual>
      <origin rpy="0 0 0" xyz="0 0 0"/>
      <geometry>
        <mesh filename="package://abb_common/meshes/irb_2400/visual/link_4.STL"/>
      </geometry>
      <material name="abb_orange"/>
    </visual>
    <collision>
      <origin rpy="0 0 0" xyz="0 0 0"/>
      <geometry>
        <mesh filename="package://abb_common/meshes/irb_2400/collision/link_4.STL"/>
      </geometry>
      <material name="yellow"/>
    </collision>
  </link>
  <link name="link_5">
    <visual>
      <origin rpy="0 0 0" xyz="0 0 0"/>
      <geometry>
        <mesh filename="package://abb_common/meshes/irb_2400/visual/link_5.STL"/>
      </geometry>
      <material name="abb_orange"/>
    </visual>
    <collision>
      <origin rpy="0 0 0" xyz="0 0 0"/>
      <geometry>
        <mesh filename="package://abb_common/meshes/irb_2400/collision/link_5.STL"/>
      </geometry>
      <material name="yellow"/>
    </collision>
  </link>
  <link name="link_6">
    <visual>
      <origin rpy="0 0 0" xyz="0 0 0"/>
      <geometry>
        <mesh filename="package://abb_common/meshes/irb_2400/visual/link_6.STL"/>
      </geometry>
      <material name="abb_orange"/>
    </visual>
    <collision>
      <origin rpy="0 0 0" xyz="0 0 0"/>
      <geometry>
        <mesh filename="package://abb_common/meshes/irb_2400/collision/link_6.STL"/>
      </geometry>
      <material name="yellow"/>
    </collision>
  </link>
  <link name="tool0"/>
  <joint name="joint_1" type="revolute">
    <origin rpy="0 0 0" xyz="0 0 0"/>
    <parent link="base_link"/>
    <child link="link_1"/>
    <axis xyz="0 0 1"/>
    <limit effort="0" lower="-3.1416" upper="3.1416" velocity="2.618"/>
    <calibration falling="0" rising="0"/>
    <dynamics damping="0" friction="0"/>
  </joint>
  <joint name="joint_2" type="revolute">
    <origin rpy="0 0 0" xyz="0.1 0 0.615"/>
    <parent link="link_1"/>
    <child link="link_2"/>
    <axis xyz="0 1 0"/>
    <limit effort="0" lower="-1.7453" upper="1.9199" velocity="2.618"/>
    <calibration falling="0" rising="0"/>
    <dynamics damping="0" friction="0"/>
  </joint>
  <joint name="joint_3" type="revolute">
    <origin rpy="0 0 0" xyz="0 0 0.705"/>
    <parent link="link_2"/>
    <child link="link_3"/>
    <axis xyz="0 1 0"/>
    <limit effort="0" lower="-1.0472" upper="1.1345" velocity="2.618"/>
    <calibration falling="0" rising="0"/>
    <dynamics damping="0" friction="0"/>
  </joint>
  <joint name="joint_4" type="revolute">
    <origin rpy="0 0 0" xyz="0.258 0 0.135"/>
    <parent link="link_3"/>
    <child link="link_4"/>
    <axis xyz="1 0 0"/>
    <limit effort="0" lower="-3.49" upper="3.49" velocity="6.2832"/>
    <calibration falling="0" rising="0"/>
    <dynamics damping="0" friction="0"/>
  </joint>
  <joint name="joint_5" type="revolute">
    <origin rpy="0 0 0" xyz="0.497 0 0"/>
    <parent link="link_4"/>
    <child link="link_5"/>
    <axis xyz="0 1 0"/>
    <limit effort="0" lower="-2.0944" upper="2.0944" velocity="6.2832"/>
    <calibration falling="0" rising="0"/>
    <dynamics damping="0" friction="0"/>
  </joint>
  <joint name="joint_6" type="revolute">
    <origin rpy="0 0 0" xyz="0.085 0 0"/>
    <parent link="link_5"/>
    <child link="link_6"/>
    <axis xyz="1 0 0"/>
    <limit effort="0" lower="-6.9813" upper="6.9813" velocity="7.854"/>
    <calibration falling="0" rising="0"/>
    <dynamics damping="0" friction="0"/>
  </joint>
  <joint name="joint_6-tool0" type="fixed">
    <parent link="link_6"/>
    <child link="tool0"/>
    <origin rpy="0 0 0" xyz="0 0 0"/>
  </joint>
  <joint name="world_to_robot" type="fixed">
    <parent link="world_frame"/>
    <child link="base_link"/>
    <origin rpy="0 0 0" xyz="0 0 0"/>
  </joint>
  <link name="table_base"/>
  <link name="table_top">
    <visual>
      <geometry>
        <box size="1.0 1.0 0.05"/>
      </geometry>
      <origin rpy="0 0 0" xyz="0 0 0"/>
    </visual>
  </link>
  <joint name="table_top" type="fixed">
    <parent link="table_base"/>
    <child link="table_top"/>
    <origin rpy="0 0 0" xyz="0 0 0.5"/>
  </joint>
  <link name="table_leg_1">
    <visual>
      <geometry>
        <box size="0.05 0.05 0.5"/>
      </geometry>
      <origin rpy="0 0 0" xyz="0 0 0"/>
    </visual>
  </link>
  <joint name="table_leg_1" type="fixed">
    <parent link="table_base"/>
    <child link="table_leg_1"/>
    <origin rpy="0 0 0" xyz="-0.5 -0.5 0.25"/>
  </joint>
  <link name="table_leg_2">
    <visual>
      <geometry>
        <box size="0.05 0.05 0.5"/>
      </geometry>
      <origin rpy="0 0 0" xyz="0 0 0"/>
    </visual>
  </link>
  <joint name="table_leg_2" type="fixed">
    <parent link="table_base"/>
    <child link="table_leg_2"/>
    <origin rpy="0 0 0" xyz="-0.5 0.5 0.25"/>
  </joint>
  <link name="table_leg_3">
    <visual>
      <geometry>
        <box size="0.05 0.05 0.5"/>
      </geometry>
      <origin rpy="0 0 0" xyz="0 0 0"/>
    </visual>
  </link>
  <joint name="table_leg_3" type="fixed">
    <parent link="table_base"/>
    <child link="table_leg_3"/>
    <origin rpy="0 0 0" xyz="0.5 0.5 0.25"/>
  </joint>
  <link name="table_leg_4">
    <visual>
      <geometry>
        <box size="0.05 0.05 0.5"/>
      </geometry>
      <origin rpy="0 0 0" xyz="0 0 0"/>
    </visual>
  </link>
  <joint name="table_leg_4" type="fixed">
    <parent link="table_base"/>
    <child link="table_leg_4"/>
    <origin rpy="0 0 0" xyz="0.5 -0.5 0.25"/>
  </joint>
  <joint name="world_to_table" type="fixed">
    <parent link="world_frame"/>
    <child link="table_base"/>
    <origin rpy="0 0 0" xyz="1.0 0 0"/>
  </joint>
</robot>
