<?xml version="1.0" ?>
<!-- =================================================================================== -->
<!-- |    This document was autogenerated by xacro from sia5.xacro                     | -->
<!-- |    EDITING THIS FILE BY HAND IS NOT RECOMMENDED                                 | -->
<!-- =================================================================================== -->
<!--Generates a urdf from the macro in sia5.macro.xacro -->
<robot name="sia5" xmlns:xacro="http://ros.org/wiki/xacro">
  <link name="base_link">
    <visual>
      <origin rpy="0 0 0" xyz="0 0 0"/>
      <geometry>
        <mesh filename="package://motoman_config/meshes/sia5/visual/base.dae"/>
      </geometry>
    </visual>
    <collision>
      <origin rpy="0 0 0" xyz="0 0 0"/>
      <geometry>
        <mesh filename="package://motoman_config/meshes/sia5/collision/base.dae"/>
      </geometry>
    </collision>
  </link>
  <link name="link_s">
    <visual>
      <origin rpy="0 0 0" xyz="0 0 0"/>
      <geometry>
        <mesh filename="package://motoman_config/meshes/sia5/visual/link_s.dae"/>
      </geometry>
    </visual>
    <collision>
      <origin rpy="0 0 0" xyz="0 0 0"/>
      <geometry>
        <mesh filename="package://motoman_config/meshes/sia5/collision/link_s.dae"/>
      </geometry>
    </collision>
  </link>
  <joint name="joint_s" type="revolute">
    <origin rpy="0 0 0" xyz="0 0 0.31"/>
    <!--r=${90*deg}-->
    <parent link="base_link"/>
    <child link="link_s"/>
    <axis xyz="0 0 1"/>
    <limit effort="0" lower="-3.14159274" upper="3.14159274" velocity="3.4906586"/>
    <safety_controller k_position="0" k_velocity="0" soft_lower_limit="0" soft_upper_limit="0"/>
  </joint>
  <link name="link_l">
    <visual>
      <origin rpy="0 0 0" xyz="0 0 0"/>
      <geometry>
        <mesh filename="package://motoman_config/meshes/sia5/visual/link_l.dae"/>
      </geometry>
    </visual>
    <collision>
      <origin rpy="0 0 0" xyz="0 0 0"/>
      <geometry>
        <mesh filename="package://motoman_config/meshes/sia5/collision/link_l.dae"/>
      </geometry>
    </collision>
  </link>
  <joint name="joint_l" type="revolute">
    <origin rpy="0 0 0" xyz="0 0 0"/>
    <parent link="link_s"/>
    <child link="link_l"/>
    <axis xyz="0 1 0"/>
    <limit effort="0" lower="-1.91986223" upper="1.91986223" velocity="3.4906586"/>
    <safety_controller k_position="0" k_velocity="0" soft_lower_limit="0" soft_upper_limit="0"/>
  </joint>
  <link name="link_e">
    <visual>
      <origin rpy="0 0 0" xyz="0 0 0"/>
      <geometry>
        <mesh filename="package://motoman_config/meshes/sia5/visual/link_e.dae"/>
      </geometry>
    </visual>
    <collision>
      <origin rpy="0 0 0" xyz="0 0 0"/>
      <geometry>
        <mesh filename="package://motoman_config/meshes/sia5/collision/link_e.dae"/>
      </geometry>
    </collision>
  </link>
  <joint name="joint_e" type="revolute">
    <origin rpy="0 0 0" xyz="0 0 0.27"/>
    <parent link="link_l"/>
    <child link="link_e"/>
    <axis xyz="0 0 1"/>
    <limit effort="0" lower="-2.96705981" upper="2.96705981" velocity="3.4906586"/>
    <safety_controller k_position="0" k_velocity="0" soft_lower_limit="0" soft_upper_limit="0"/>
  </joint>
  <link name="link_u">
    <visual>
      <origin rpy="0 0 0" xyz="0 0 0"/>
      <geometry>
        <mesh filename="package://motoman_config/meshes/sia5/visual/link_u.dae"/>
      </geometry>
    </visual>
    <collision>
      <origin rpy="0 0 0" xyz="0 0 0"/>
      <geometry>
        <mesh filename="package://motoman_config/meshes/sia5/collision/link_u.dae"/>
      </geometry>
    </collision>
  </link>
  <joint name="joint_u" type="revolute">
    <origin rpy="0 0 0" xyz="0.085 0 0"/>
    <parent link="link_e"/>
    <child link="link_u"/>
    <axis xyz="0 1 0"/>
    <limit effort="0" lower="-1.57079637" upper="2.007128695" velocity="3.4906586"/>
    <safety_controller k_position="0" k_velocity="0" soft_lower_limit="0" soft_upper_limit="0"/>
  </joint>
  <link name="link_r">
    <visual>
      <origin rpy="0 0 0" xyz="0 0 0"/>
      <geometry>
        <mesh filename="package://motoman_config/meshes/sia5/visual/link_r.dae"/>
      </geometry>
    </visual>
    <collision>
      <origin rpy="0 0 0" xyz="0 0 0"/>
      <geometry>
        <mesh filename="package://motoman_config/meshes/sia5/collision/link_r.dae"/>
      </geometry>
    </collision>
  </link>
  <joint name="joint_r" type="revolute">
    <origin rpy="0 0 0" xyz="0.27 0 0.06"/>
    <parent link="link_u"/>
    <child link="link_r"/>
    <axis xyz="-1 0 0"/>
    <limit effort="0" lower="-1.57079637" upper="1.57079637" velocity="3.4906586"/>
    <safety_controller k_position="0" k_velocity="0" soft_lower_limit="0" soft_upper_limit="0"/>
  </joint>
  <link name="link_b">
    <visual>
      <origin rpy="0 0 0" xyz="0 0 0"/>
      <geometry>
        <mesh filename="package://motoman_config/meshes/sia5/visual/link_b.dae"/>
      </geometry>
    </visual>
    <collision>
      <origin rpy="0 0 0" xyz="0 0 0"/>
      <geometry>
        <mesh filename="package://motoman_config/meshes/sia5/collision/link_b.dae"/>
      </geometry>
    </collision>
  </link>
  <joint name="joint_b" type="revolute">
    <origin rpy="0 0 0" xyz="0 0 0"/>
    <parent link="link_r"/>
    <child link="link_b"/>
    <axis xyz="0 1 0"/>
    <limit effort="0" lower="-1.91986223" upper="1.91986223" velocity="4.01425739"/>
    <safety_controller k_position="0" k_velocity="0" soft_lower_limit="0" soft_upper_limit="0"/>
  </joint>
  <link name="link_t">
    <visual>
      <origin rpy="0 0 0" xyz="0 0 0"/>
      <geometry>
        <mesh filename="package://motoman_config/meshes/sia5/visual/link_t.dae"/>
      </geometry>
    </visual>
    <collision>
      <origin rpy="0 0 0" xyz="0 0 0"/>
      <geometry>
        <mesh filename="package://motoman_config/meshes/sia5/collision/link_t.dae"/>
      </geometry>
    </collision>
  </link>
  <joint name="joint_t" type="revolute">
    <origin rpy="0 0 0" xyz="0.134 0 0"/>
    <parent link="link_b"/>
    <child link="link_t"/>
    <axis xyz="-1 0 0"/>
    <limit effort="0" lower="-1.57079637" upper="1.57079637" velocity="6.10865255"/>
    <safety_controller k_position="0" k_velocity="0" soft_lower_limit="0" soft_upper_limit="0"/>
  </joint>
  <link name="tool0"/>
  <joint name="link_t-tool0" type="fixed">
    <origin rpy="0 0 0" xyz="0.011 0 0"/>
    <parent link="link_t"/>
    <child link="tool0"/>
  </joint>
</robot>

